Workbook

Sheet Sheet1
B1: 계좌 | D1: 거래처 | E1: 은행 | F1: 이름 | G1: 부가세유무
A2: 020 | B2: 1005504775443 | C2: 71000 | D2: 히피스 | E2: 우리 | F2: 이도영(히피스) | G2: ㅇ | H2: X | I2: 45992
A3: 020 | B3: 1005804834765 | C3: 18000 | D3: 홈런 | E3: 우리 | F3: ㈜플레이 홈런 | G3: ㅇ | H3: X | I3: 45992
A4: 088 | B4: 110554774968 | C4: 198000 | D4: 하이앤땡큐 | E4: 신한 | F4: 김승현 | G4: ㅇ | H4: X | I4: 45992
A5: 081 | B5: 17191028203607 | C5: 10000 | D5: 하이바 | E5: 하나 | F5: 김태형 | G5: ㅇ | H5: X | I5: 45992
A6: 004 | B6: 09180104175091 | C6: 200000 | D6: 하멜 | E6: 국민 | F6: 우환균(하멜) | G6: ㅇ | H6: X | I6: 45992
A7: 004 | B7: 80750104288480 | C7: 2858500 | D7: 필앤마조 | E7: 국민 | F7: (주)필앤마조 | G7: ㅇ | H7: X | I7: 45992
A8: 088 | B8: 110604500814 | C8: 21000 | D8: 피크닉 | E8: 신한 | F8: 피크닉 | G8: ㅇ | H8: X | I8: 45992
A9: 004 | B9: 07300104259173 | C9: 468000 | D9: 프레쩰 | E9: 국민 | F9: 주현 | G9: ㅇ | H9: X | I9: 45992
A10: 088 | B10: 140013540787 | C10: 280000 | D10: 풀하우스 | E10: 신한 | F10: 주식회사 풀하우스컴퍼니 김기완 | G10: ㅇ | H10: X | I10: 45992
A11: 088 | B11: 110316175919 | C11: 72000 | D11: 페어립트 | E11: 신한 | F11: 황두환(페어립트) | G11: ㅇ | H11: X | I11: 45992
A12: 088 | B12: 110564250069 | C12: 100000 | D12: 펀치 | E12: 신한 | F12: 양창민(펀치) | G12: ㅇ | H12: X | I12: 45992
A13: 003 | B13: 01819320404015 | C13: 112750 | D13: 퍼플그레이 | E13: 기업 | F13: ㈜퍼플그레이어패럴 | G13: ㅇ | H13: O | I13: 45992
A14: 088 | B14: 110489581929 | C14: 10000 | D14: 팔로우비 | E14: 신한 | F14: 변입섭 팔로우비 | G14: ㅇ | H14: X | I14: 45992
A15: 088 | B15: 110555436511 | C15: 388000 | D15: 파인파인 | E15: 신한 | F15: 파인파인 | G15: ㅇ | H15: X | I15: 45992
A16: 088 | B16: 140014915730 | C16: 206000 | D16: 티오 | E16: 신한 | F16: ㈜패션컴퍼니오성 | G16: ㅇ | H16: X | I16: 45992
A17: 020 | B17: 1005603272336 | C17: 132000 | D17: 트웬티 | E17: 우리 | F17: 이한숙 | G17: ㅇ | H17: X | I17: 45992
A18: 003 | B18: 02314297601014 | C18: 44000 | D18: 키치키치 | E18: 기업 | F18: ㈜마젠타어패럴그룹 | G18: ㅇ | H18: O | I18: 45992
A19: 003 | B19: 01212165604012 | C19: 338250 | D19: 크림베이지 | E19: 기업 | F19: 주식회사 크림베이지어패럴 | G19: ㅇ | H19: O | I19: 45992
A20: 004 | B20: 34780104162710 | C20: 200000 | D20: 크레파스 | E20: 국민 | F20: ㈜투앤드컴퍼니 | G20: ㅇ | H20: X | I20: 45992
A21: 003 | B21: 01500000197711 | C21: 760100 | D21: 케이디지 | E21: 기업 | F21: 케이디지 | G21: ㅇ | H21: O | I21: 45992
A22: 020 | B22: 1005003797667 | C22: 239000 | D22: 컴온 | E22: 우리 | F22: ㈜에이치케이더블류컴퍼니 | G22: ㅇ | H22: X | I22: 45992
A23: 004 | B23: 59280104131903 | C23: 10000 | D23: 치퍼 | E23: 국민 | F23: 최현준(치퍼(CHIPPER)) | G23: ㅇ | H23: X | I23: 45992
A24: 004 | B24: 80750104288141 | C24: 14000 | D24: 춘샤 | E24: 국민 | F24: 김유미(춘샤) | G24: ㅇ | H24: X | I24: 45992
A25: 088 | B25: 140012386934 | C25: 12000 | D25: 지엔 | E25: 신한 | F25: ㈜지엔어패럴 | G25: ㅇ | H25: X | I25: 45992
A26: 004 | B26: 77463704004031 | C26: 155000 | D26: 줄리 | E26: 국민 | F26: ㈜쥴리 | G26: ㅇ | H26: X | I26: 45992
... A130: 003 | B130: 06911960504017 | C130: 32000 | D130: 엠제이 | E130: 기업 | F130: 주식회사엠제이룩 | G130: ㅇ | H130: X | I130: 45993
A131: 088 | B131: 110425567853 | C131: 28000 | D131: 엘로즈 | E131: 신한 | F131: 이현승엘로즈 | G131: ㅇ | H131: X | I131: 45993
A132: 088 | B132: 110517059780 | C132: 27500 | D132: 엔초 | E132: 신한 | F132: 최훈정(엔초) | G132: ㅇ | H132: O | I132: 45993
A133: 003 | B133: 02908577101019 | C133: 0 | D133: 에이에이더블유 | E133: 기업 | F133: 에이에이더블유(권지영) | G133: ㅇ | H133: O | I133: 45993
A134: 004 | B134: 21830104363558 | C134: 19000 | D134: 에이러브 | E134: 국민 | F134: 임애경 | G134: ㅇ | H134: X | I134: 45993
A135: 003 | B135: 01093570559 | C135: 44000 | D135: 야나 | E135: 기업 | F135: 김정훈(야나) | G135: ㅇ | H135: X | I135: 45993
A136: 088 | B136: 110539887153 | C136: 509000 | D136: 안나 | E136: 신한 | F136: 김수진 | G136: ㅇ | H136: X | I136: 45993
A137: 020 | B137: 1005203796625 | C137: 714000 | D137: 아이티 | E137: 우리 | F137: HKW컴퍼니 | G137: ㅇ | H137: X | I137: 45993
A138: 088 | B138: 110458824187 | C138: 42000 | D138: 썸모어 | E138: 신한 | F138: 오재훈 | G138: ㅇ | H138: X | I138: 45993
A139: 004 | B139: 77460104250367 | C139: 110000 | D139: 심플 | E139: 국민 | F139: 김현아(심플) | G139: ㅇ | H139: X | I139: 45993
A140: 081 | B140: 38891000310908 | C140: 144000 | D140: 슈퍼스타 | E140: 하나 | F140: 김학영 | G140: ㅇ | H140: X | I140: 45993
A141: 088 | B141: 140014903450 | C141: 43000 | D141: 슈퍼땅콩 | E141: 신한 | F141: 슈퍼땅콩 | G141: ㅇ | H141: X | I141: 45993
A142: 081 | B142: 20791052452207 | C142: 58000 | D142: 뿌 | E142: 하나 | F142: 이준미 | G142: ㅇ | H142: X | I142: 45993
A143: 088 | B143: 110525476734 | C143: 10000 | D143: 뽀숑 | E143: 신한 | F143: 이송희 | G143: ㅇ | H143: X | I143: 45993
...

Sheet Sheet3

Sheet Sheet8
A1: ㅇ | B1: ㅇ | C1: ㅇ | D1: ㅇ | E1: ㅇ | F1: ㅇ | G1: ㅇ | H1: ㅇ
A2: 020 | B2: 1005603106537 | C2: 540000 | D2: 힙블리 | E2: 우리 | F2: 오승미 | G2: ㅇ | H2: x
A3: 020 | B3: 1005504775443 | C3: 141000 | D3: 히피스 | E3: 우리 | F3: 이도영(히피스) | G3: ㅇ | H3: X
A4: 088 | B4: 110607909500 | C4: 1800000 | D4: 후크 | E4: 신한 | F4: 최문수 | G4: ㅇ | H4: X
A5: 090 | B5: 3333289511795 | C5: 8000 | D5: 하이프 | E5: 카카오 | F5: 하이프(HYPE) | G5: ㅇ | H5: X
A6: 088 | B6: 110554774968 | C6: 510000 | D6: 하이앤땡큐 | E6: 신한 | F6: 김승현 | G6: ㅇ | H6: X
A7: 081 | B7: 17191028203607 | C7: 10000 | D7: 하이바 | E7: 하나 | F7: 김태형 | G7: ㅇ | H7: X
A8: 004 | B8: 80750104288480 | C8: 2460000 | D8: 필앤마조 | E8: 국민 | F8: (주)필앤마조 | G8: ㅇ | H8: X
A9: 088 | B9: 110604500814 | C9: 28000 | D9: 피크닉 | E9: 신한 | F9: 피크닉 | G9: ㅇ | H9: X
A10: 004 | B10: 07300104259173 | C10: 780000 | D10: 프레쩰 | E10: 국민 | F10: 주현 | G10: ㅇ | H10: X
A11: 088 | B11: 140013540787 | C11: 41000 | D11: 풀하우스 | E11: 신한 | F11: 주식회사 풀하우스컴퍼니 김기완 | G11: ㅇ | H11: X
A12: 090 | B12: 3333123250772 | C12: 45000 | D12: 포레나 | E12: 카카오 | F12: 박진성 | G12: ㅇ | H12: X
A13: 088 | B13: 110316175919 | C13: 24000 | D13: 페어립트 | E13: 신한 | F13: 황두환(페어립트) | G13: ㅇ | H13: X
A14: 003 | B14: 01819320404015 | C14: 66550 | D14: 퍼플그레이 | E14: 기업 | F14: ㈜퍼플그레이어패럴 | G14: ㅇ | H14: O
A15: 088 | B15: 110555436511 | C15: 96000 | D15: 파인파인 | E15: 신한 | F15: 파인파인 | G15: ㅇ | H15: X
A16: 088 | B16: 140014915730 | C16: 144000 | D16: 티오 | E16: 신한 | F16: ㈜패션컴퍼니오성 | G16: ㅇ | H16: X
A17: 011 | B17: 3022043205911 | C17: 24000 | D17: 투썸 | E17: 농협 | F17: 투썸 | G17: ㅇ | H17: X
A18: 004 | B18: 21830104388492 | C18: 42000 | D18: 크림 | E18: 국민 | F18: 박종수 | G18: ㅇ | H18: X
A19: 081 | B19: 28491002673804 | C19: 2279200 | D19: 코디63 | E19: 하나 | F19: ㈜코디63 | G19: ㅇ | H19: O
A20: 003 | B20: 01500000197711 | C20: 377300 | D20: 케이디지 | E20: 기업 | F20: 케이디지 | G20: ㅇ | H20: O
A21: 020 | B21: 1005003797667 | C21: 445000 | D21: 컴온 | E21: 우리 | F21: ㈜에이치케이더블류컴퍼니 | G21: ㅇ | H21: X
A22: 004 | B22: 59280104131903 | C22: 7000 | D22: 치퍼 | E22: 국민 | F22: 최현준(치퍼(CHIPPER)) | G22: ㅇ | H22: X
A23: 003 | B23: 50003222004019 | C23: 8800 | D23: 진머니 | E23: 기업 | F23: ㈜진머니 | G23: ㅇ | H23: O
A24: 081 | B24: 13502366500508 | C24: 105000 | D24: 제이케이 | E24: 하나 | F24: 김진규 | G24: ㅇ | H24: X
... A32: 081 | B32: 27991001398304 | C32: 75000 | D32: 이고 | E32: 하나 | F32: 더원컴퍼니 | G32: ㅇ | H32: X
A33: 090 | B33: 3333095154900 | C33: 6000 | D33: 유엑스미 | E33: 카카오 | F33: 안소연 | G33: ㅇ | H33: X
A34: 088 | B34: 110565571708 | C34: 10000 | D34: 유에이드 | E34: 신한 | F34: 유에이드(정연화) | G34: ㅇ | H34: X
A35: 004 | B35: 00570104181266 | C35: 1092000 | D35: 유스픽 | E35: 국민 | F35: 유성진 | G35: ㅇ | H35: X
A36: 081 | B36: 39091033424807 | C36: 12000 | D36: 유스 | E36: 하나 | F36: 최민준(유스) | G36: ㅇ | H36: X
A37: 088 | B37: 110224033860 | C37: 180000 | D37: 유리 | E37: 신한 | F37: 박성은 | G37: ㅇ | H37: X
A38: 090 | B38: 3333267395045 | C38: 25000 | D38: 유니모어 | E38: 카카오 | F38: 이석일(유니모어) | G38: ㅇ | H38: x
A39: 004 | B39: 17130104207865 | C39: 85000 | D39: 윌 | E39: 국민 | F39: 김성희(윌) | G39: ㅇ | H39: X
A40: 081 | B40: 22191002103004 | C40: 190300 | D40: 위클리 | E40: 하나 | F40: 주식회사제이와이글로벌패션그룹 | G40: ㅇ | H40: O
A41: 020 | B41: 1005104702925 | C41: 76000 | D41: 우트 | E41: 우리 | F41: ㈜오오티제이 오리진 | G41: ㅇ | H41: O
A42: 088 | B42: 110367521470 | C42: 1135000 | D42: 요미요미 | E42: 신한 | F42: 이정규(요미요미) | G42: ㅇ | H42: X
A43: 003 | B43: 03014345804019 | C43: 26000 | D43: 오드 | E43: 기업 | F43: 주식회사 오드점 | G43: ㅇ | H43: X
A44: 088 | B44: 110555467484 | C44: 14000 | D44: 오도시 | E44: 신한 | F44: 임창현/오도시 | G44: ㅇ | H44: X
A45: 020 | B45: 1005504495386 | C45: 32000 | D45: 여기 | E45: 우리 | F45: 에브리웨어 | G45: ㅇ | H45: X
A46: 003 | B46: 06911960504017 | C46: 36000 | D46: 엠제이 | E46: 기업 | F46: 주식회사엠제이룩 | G46: ㅇ | H46: X
A47: 088 | B47: 110425567853 | C47: 27000 | D47: 엘로즈 | E47: 신한 | F47: 이현승엘로즈 | G47: ㅇ | H47: X
...

Sheet Sheet2
A1: ㅇ | B1: ㅇ | C1: ㅇ | D1: ㅇ | E1: ㅇ | F1: ㅇ | G1: ㅇ | H1: ㅇ
A2: 020 | B2: 1005504775443 | C2: 8000 | D2: 히피스 | E2: 우리 | F2: 이도영(히피스) | G2: ㅇ | H2: X
A3: 088 | B3: 110607909500 | C3: 18000 | D3: 후크 | E3: 신한 | F3: 최문수 | G3: ㅇ | H3: X
A4: 020 | B4: 1005804834765 | C4: 9000 | D4: 홈런 | E4: 우리 | F4: ㈜플레이 홈런 | G4: ㅇ | H4: X
A5: 088 | B5: 110554774968 | C5: 32000 | D5: 하이앤땡큐 | E5: 신한 | F5: 김승현 | G5: ㅇ | H5: X
A6: 081 | B6: 17191028203607 | C6: 54000 | D6: 하이바 | E6: 하나 | F6: 김태형 | G6: ㅇ | H6: X
A7: 004 | B7: 80750104288480 | C7: 9000 | D7: 필앤마조 | E7: 국민 | F7: (주)필앤마조 | G7: ㅇ | H7: X
A8: 088 | B8: 110604500814 | C8: 14000 | D8: 피크닉 | E8: 신한 | F8: 피크닉 | G8: ㅇ | H8: X
A9: 090 | B9: 3333123250772 | C9: 99000 | D9: 포레나 | E9: 카카오 | F9: 박진성 | G9: ㅇ | H9: X
A10: 088 | B10: 110316175919 | C10: 24000 | D10: 페어립트 | E10: 신한 | F10: 황두환(페어립트) | G10: ㅇ | H10: X
A11: 003 | B11: 01819320404015 | C11: 39600 | D11: 퍼플그레이 | E11: 기업 | F11: ㈜퍼플그레이어패럴 | G11: ㅇ | H11: O
A12: 088 | B12: 110489581929 | C12: 10000 | D12: 팔로우비 | E12: 신한 | F12: 변입섭 팔로우비 | G12: ㅇ | H12: X
A13: 088 | B13: 140014915730 | C13: 18000 | D13: 티오 | E13: 신한 | F13: ㈜패션컴퍼니오성 | G13: ㅇ | H13: X
A14: 020 | B14: 1005603272336 | C14: 12000 | D14: 트웬티 | E14: 우리 | F14: 이한숙 | G14: ㅇ | H14: X
A15: 003 | B15: 01212165604012 | C15: 606100 | D15: 크림베이지 | E15: 기업 | F15: 주식회사 크림베이지어패럴 | G15: ㅇ | H15: O
A16: 004 | B16: 34780104162710 | C16: 142000 | D16: 크레파스 | E16: 국민 | F16: ㈜투앤드컴퍼니 | G16: ㅇ | H16: X
A17: 081 | B17: 28491002673804 | C17: 528000 | D17: 코디63 | E17: 하나 | F17: ㈜코디63 | G17: ㅇ | H17: O
A18: 003 | B18: 01500000197711 | C18: 330000 | D18: 케이디지 | E18: 기업 | F18: 케이디지 | G18: ㅇ | H18: O
A19: 004 | B19: 80750104288141 | C19: 14000 | D19: 춘샤 | E19: 국민 | F19: 김유미(춘샤) | G19: ㅇ | H19: X
A20: 088 | B20: 140012386934 | C20: 72000 | D20: 지엔 | E20: 신한 | F20: ㈜지엔어패럴 | G20: ㅇ | H20: X
A21: 004 | B21: 79660104099780 | C21: 10000 | D21: 제임스 | E21: 국민 | F21: ㈜더블유에이치컴퍼니 | G21: ㅇ | H21: X
A22: 081 | B22: 13502366500508 | C22: 84000 | D22: 제이케이 | E22: 하나 | F22: 김진규 | G22: ㅇ | H22: X
A23: 004 | B23: 09340104281400 | C23: 42500 | D23: 제이원 | E23: 국민 | F23: 이경목(제이원) | G23: ㅇ | H23: X
A24: 003 | B24: 08606527904019 | C24: 250000 | D24: 일프로 | E24: 기업 | F24: ㈜더일프로 | G24: ㅇ | H24: X
... A29: 020 | B29: 1005404565023 | C29: 27000 | D29: 유돈노미 | E29: 우리 | F29: 유돈노미 | G29: ㅇ | H29: X
A30: 090 | B30: 3333267395045 | C30: 12000 | D30: 유니모어 | E30: 카카오 | F30: 이석일(유니모어) | G30: ㅇ | H30: x
A31: 081 | B31: 22191002103004 | C31: 213400 | D31: 위클리 | E31: 하나 | F31: 주식회사제이와이글로벌패션그룹 | G31: ㅇ | H31: O
A32: 020 | B32: 1005104702925 | C32: 36000 | D32: 우트 | E32: 우리 | F32: ㈜오오티제이 오리진 | G32: ㅇ | H32: O
A33: 088 | B33: 110367521470 | C33: 9000 | D33: 요미요미 | E33: 신한 | F33: 이정규(요미요미) | G33: ㅇ | H33: X
A34: 088 | B34: 140015691630 | C34: 39500 | D34: 오드 | E34: 신한 | F34: 주식회사 오드점 | G34: ㅇ | H34: X
A35: 088 | B35: 110555467484 | C35: 68000 | D35: 오도시 | E35: 신한 | F35: 임창현/오도시 | G35: ㅇ | H35: X
A36: 020 | B36: 1005504495386 | C36: 12000 | D36: 여기 | E36: 우리 | F36: 에브리웨어 | G36: ㅇ | H36: X
A37: 088 | B37: 140013987091 | C37: 56000 | D37: 엣지 | E37: 신한 | F37: ㈜이디지이(EDGE) | G37: ㅇ | H37: X
A38: 003 | B38: 06911960504017 | C38: 36000 | D38: 엠제이 | E38: 기업 | F38: 주식회사엠제이룩 | G38: ㅇ | H38: X
A39: 003 | B39: 02908577101019 | C39: 256300 | D39: 에이에이더블유 | E39: 기업 | F39: 에이에이더블유(권지영) | G39: ㅇ | H39: O
A40: 004 | B40: 21830104363558 | C40: 12000 | D40: 에이러브 | E40: 국민 | F40: 임애경 | G40: ㅇ | H40: X
A41: 020 | B41: 1005804294993 | C41: 45000 | D41: 얼리모닝 | E41: 우리 | F41: 백승갑 | G41: ㅇ | H41: X
A42: 011 | B42: 3021427284011 | C42: 50000 | D42: 언니제이 | E42: 농협 | F42: 고연정(언니제이) | G42: ㅇ | H42: X
A43: 081 | B43: 18291003287104 | C43: 32000 | D43: 안느 | E43: 하나 | F43: ㈜몬드 | G43: ㅇ | H43: X
A44: 088 | B44: 110539887153 | C44: 619000 | D44: 안나 | E44: 신한 | F44: 김수진 | G44: ㅇ | H44: X
...

Sheet 1월 22일
A1: ㅇ | B1: ㅇ | C1: ㅇ | D1: ㅇ | E1: ㅇ | F1: ㅇ | G1: ㅇ | H1: ㅇ
A2: 020 | B2: 1005504775443 | C2: 41000 | D2: 히피스 | E2: 우리 | F2: 이도영(히피스) | G2: ㅇ | H2: X
A3: 003 | B3: 20108343304014 | C3: 9000 | D3: 화이트옐로우 | E3: 기업 | F3: 옐로우이엔엠 주식회사 | G3: ㅇ | H3: X
A4: 020 | B4: 1005603730629 | C4: 8000 | D4: 홀리몰리 | E4: 우리 | F4: 홀리몰리 | G4: ㅇ | H4: X
A5: 088 | B5: 110554774968 | C5: 64000 | D5: 하이앤땡큐 | E5: 신한 | F5: 김승현 | G5: ㅇ | H5: X
A6: 004 | B6: 80750104288480 | C6: 1435000 | D6: 필앤마조 | E6: 국민 | F6: (주)필앤마조 | G6: ㅇ | H6: X
A7: 004 | B7: 79660104121302 | C7: 7000 | D7: 푸딩 | E7: 국민 | F7: 박혜민 | G7: ㅇ | H7: X
A8: 090 | B8: 3333123250772 | C8: 18000 | D8: 포레나 | E8: 카카오 | F8: 박진성 | G8: ㅇ | H8: X
A9: 088 | B9: 110316175919 | C9: 48000 | D9: 페어립트 | E9: 신한 | F9: 황두환(페어립트) | G9: ㅇ | H9: X
A10: 088 | B10: 110564250069 | C10: 7000 | D10: 펀치 | E10: 신한 | F10: 양창민(펀치) | G10: ㅇ | H10: X
A11: 003 | B11: 01819320404015 | C11: 1650 | D11: 퍼플그레이 | E11: 기업 | F11: ㈜퍼플그레이어패럴 | G11: ㅇ | H11: O
A12: 088 | B12: 140014915730 | C12: 6000 | D12: 티오 | E12: 신한 | F12: ㈜패션컴퍼니오성 | G12: ㅇ | H12: X
A13: 011 | B13: 3022043205911 | C13: 12000 | D13: 투썸 | E13: 농협 | F13: 투썸 | G13: ㅇ | H13: X
A14: 004 | B14: 34780104162710 | C14: 130000 | D14: 크레파스 | E14: 국민 | F14: ㈜투앤드컴퍼니 | G14: ㅇ | H14: X
A15: 081 | B15: 28491002673804 | C15: 510400 | D15: 코디63 | E15: 하나 | F15: ㈜코디63 | G15: ㅇ | H15: O
A16: 003 | B16: 01500000197711 | C16: 414150 | D16: 케이디지 | E16: 기업 | F16: 케이디지 | G16: ㅇ | H16: O
A17: 004 | B17: 59280104131903 | C17: 35000 | D17: 치퍼 | E17: 국민 | F17: 최현준(치퍼(CHIPPER)) | G17: ㅇ | H17: X
A18: 088 | B18: 140012386934 | C18: 120000 | D18: 지엔 | E18: 신한 | F18: ㈜지엔어패럴 | G18: ㅇ | H18: X
A19: 081 | B19: 28191003840204 | C19: 8000 | D19: 저기 | E19: 하나 | F19: 에브리웨어 | G19: ㅇ | H19: X
A20: 081 | B20: 21891004070404 | C20: 12000 | D20: 이안 | E20: 하나 | F20: 주식회사 데이앤 | G20: ㅇ | H20: X
... A23: 020 | B23: 1005404565023 | C23: 13500 | D23: 유돈노미 | E23: 우리 | F23: 유돈노미 | G23: ㅇ | H23: X
A24: 090 | B24: 3333267395045 | C24: 12000 | D24: 유니모어 | E24: 카카오 | F24: 이석일(유니모어) | G24: ㅇ | H24: x
A25: 081 | B25: 22191002103004 | C25: 338800 | D25: 위클리 | E25: 하나 | F25: 주식회사제이와이글로벌패션그룹 | G25: ㅇ | H25: O
A26: 088 | B26: 110367521470 | C26: 1149000 | D26: 요미요미 | E26: 신한 | F26: 이정규(요미요미) | G26: ㅇ | H26: X
A27: 088 | B27: 140012598030 | C27: 6000 | D27: 오즈브릿지 | E27: 신한 | F27: ㈜오즈브릿지 | G27: ㅇ | H27: X
A28: 088 | B28: 140015691630 | C28: 25000 | D28: 오드 | E28: 신한 | F28: 주식회사 오드점 | G28: ㅇ | H28: X
A29: 020 | B29: 1005504495386 | C29: 144000 | D29: 여기 | E29: 우리 | F29: 에브리웨어 | G29: ㅇ | H29: X
A30: 088 | B30: 140013987091 | C30: 66000 | D30: 엣지 | E30: 신한 | F30: ㈜이디지이(EDGE) | G30: ㅇ | H30: X
A31: 088 | B31: 140013987091 | C31: 60000 | D31: 엣지 | E31: 신한 | F31: ㈜이디지이(EDGE) | G31: ㅇ | H31: X
A32: 088 | B32: 110425567853 | C32: 9000 | D32: 엘로즈 | E32: 신한 | F32: 이현승엘로즈 | G32: ㅇ | H32: X
A33: 003 | B33: 02908577101019 | C33: 123200 | D33: 에이에이더블유 | E33: 기업 | F33: 에이에이더블유(권지영) | G33: ㅇ | H33: O
A34: 088 | B34: 110539887153 | C34: 20000 | D34: 안나 | E34: 신한 | F34: 김수진 | G34: ㅇ | H34: X
A35: 020 | B35: 1005203796625 | C35: 804000 | D35: 아이티 | E35: 우리 | F35: HKW컴퍼니 | G35: ㅇ | H35: X
A36: 004 | B36: 00730104080518 | C36: 18000 | D36: 썸머 | E36: 국민 | F36: 최환준 | G36: ㅇ | H36: x
A37: 088 | B37: 110564935137 | C37: 17000 | D37: 스크램블 | E37: 신한 | F37: 스크램블 | G37: ㅇ | H37: X
A38: 081 | B38: 38891000310908 | C38: 121000 | D38: 슈퍼스타 | E38: 하나 | F38: 김학영 | G38: ㅇ | H38: X
A39: 020 | B39: 1005303657353 | C39: 37000 | D39: 빨주노초 | E39: 우리 | F39: 정종인 | G39: ㅇ | H39: X
A40: 004 | B40: 93390101228298 | C40: 120000 | D40: 브이브이브이 | E40: 국민 | F40: 권순범(브이브이브이) | G40: ㅇ | H40: X
A41: 004 | B41: 34780104163197 | C41: 31000 | D41: 별대봉 | E41: 국민 | F41: ㈜투앤드컴퍼니 | G41: ㅇ | H41: X
A42: 020 | B42: 1005404854052 | C42: 21000 | D42: 베베 | E42: 우리 | F42: ㈜베베픽 | G42: ㅇ | H42: X
...

Sheet 1월 23일
A1: d | B1: d | C1: d | D1: d | E1: d | F1: d | H1: d
A2: 090 | B2: 3333289511795 | C2: 243000 | D2: 하이프 | E2: 카카오 | F2: 하이프(HYPE) | G2: ㅇ | H2: X
A3: 081 | B3: 17191028203607 | C3: 9000 | D3: 하이바 | E3: 하나 | F3: 김태형 | G3: ㅇ | H3: X
A4: 003 | B4: 01041961598 | C4: 26000 | D4: 플레이 | E4: 기업 | F4: 김미라(플레이) | G4: ㅇ | H4: X
A5: 004 | B5: 07300104259173 | C5: 2184000 | D5: 프레쩰 | E5: 국민 | F5: 주현 | G5: ㅇ | H5: X
A6: 088 | B6: 140013540787 | C6: 14000 | D6: 풀하우스 | E6: 신한 | F6: 주식회사 풀하우스컴퍼니 김기완 | G6: ㅇ | H6: X
A7: 090 | B7: 3333123250772 | C7: 9000 | D7: 포레나 | E7: 카카오 | F7: 박진성 | G7: ㅇ | H7: X
A8: 088 | B8: 110316175919 | C8: 24000 | D8: 페어립트 | E8: 신한 | F8: 황두환(페어립트) | G8: ㅇ | H8: X
A9: 020 | B9: 1005602130034 | C9: 15000 | D9: 퍼블릭 | E9: 우리 | F9: ㈜진성 | G9: ㅇ | H9: X
A10: 088 | B10: 110555436511 | C10: 17000 | D10: 파인파인 | E10: 신한 | F10: 파인파인 | G10: ㅇ | H10: X
A11: 088 | B11: 140014915730 | C11: 30000 | D11: 티오 | E11: 신한 | F11: ㈜패션컴퍼니오성 | G11: ㅇ | H11: X
A12: 020 | B12: 1005603272336 | C12: 12000 | D12: 트웬티 | E12: 우리 | F12: 이한숙 | G12: ㅇ | H12: X
A13: 003 | B13: 01212165604012 | C13: 241450 | D13: 크림베이지 | E13: 기업 | F13: 주식회사 크림베이지어패럴 | G13: ㅇ | H13: O
A14: 004 | B14: 34780104162710 | C14: 15000 | D14: 크레파스 | E14: 국민 | F14: ㈜투앤드컴퍼니 | G14: ㅇ | H14: X
A15: 081 | B15: 28491002673804 | C15: 1630200 | D15: 코디63 | E15: 하나 | F15: ㈜코디63 | G15: ㅇ | H15: O
A16: 003 | B16: 01500000197711 | C16: 284350 | D16: 케이디지 | E16: 기업 | F16: 케이디지 | G16: ㅇ | H16: O
A17: 004 | B17: 59280104131903 | C17: 11000 | D17: 치퍼 | E17: 국민 | F17: 최현준(치퍼(CHIPPER)) | G17: ㅇ | H17: X
A18: 003 | B18: 50003222004019 | C18: 13200 | D18: 진머니 | E18: 기업 | F18: ㈜진머니 | G18: ㅇ | H18: O
A19: 088 | B19: 140012386934 | C19: 11000 | D19: 지엔 | E19: 신한 | F19: ㈜지엔어패럴 | G19: ㅇ | H19: X
... A30: 088 | B30: 110224033860 | C30: 90000 | D30: 유리 | E30: 신한 | F30: 박성은 | G30: ㅇ | H30: X
A31: 090 | B31: 3333267395045 | C31: 25000 | D31: 유니모어 | E31: 카카오 | F31: 이석일(유니모어) | G31: ㅇ | H31: x
A32: 081 | B32: 22191002103004 | C32: 82500 | D32: 위클리 | E32: 하나 | F32: 주식회사제이와이글로벌패션그룹 | G32: ㅇ | H32: O
A33: 088 | B33: 110367521470 | C33: 24000 | D33: 요미요미 | E33: 신한 | F33: 이정규(요미요미) | G33: ㅇ | H33: X
A34: 003 | B34: 08606445401018 | C34: 28000 | D34: 오드블루 | E34: 기업 | F34: 이성현 | G34: ㅇ | H34: X
A35: 088 | B35: 140015691630 | C35: 14500 | D35: 오드 | E35: 신한 | F35: 주식회사 오드점 | G35: ㅇ | H35: X
A36: 088 | B36: 110555467484 | C36: 28000 | D36: 오도시 | E36: 신한 | F36: 임창현/오도시 | G36: ㅇ | H36: X
A37: 020 | B37: 1005504495386 | C37: 60000 | D37: 여기 | E37: 우리 | F37: 에브리웨어 | G37: ㅇ | H37: X
A38: 088 | B38: 110425567853 | C38: 18000 | D38: 엘로즈 | E38: 신한 | F38: 이현승엘로즈 | G38: ㅇ | H38: X
A39: 003 | B39: 02908577101019 | C39: 15400 | D39: 에이에이더블유 | E39: 기업 | F39: 에이에이더블유(권지영) | G39: ㅇ | H39: O
A40: 088 | B40: 110539887153 | C40: 349000 | D40: 안나 | E40: 신한 | F40: 김수진 | G40: ㅇ | H40: X
A41: 020 | B41: 1005203796625 | C41: 16000 | D41: 아이티 | E41: 우리 | F41: HKW컴퍼니 | G41: ㅇ | H41: X
A42: 088 | B42: 110564935137 | C42: 15000 | D42: 스크램블 | E42: 신한 | F42: 스크램블 | G42: ㅇ | H42: X
A43: 081 | B43: 38891000310908 | C43: 11000 | D43: 슈퍼스타 | E43: 하나 | F43: 김학영 | G43: ㅇ | H43: X
A44: 088 | B44: 140014903450 | C44: 27000 | D44: 슈퍼땅콩 | E44: 신한 | F44: 슈퍼땅콩 | G44: ㅇ | H44: X
A45: 004 | B45: 93390101228298 | C45: 34000 | D45: 브이브이브이 | E45: 국민 | F45: 권순범(브이브이브이) | G45: ㅇ | H45: X
A46: 088 | B46: 140015691122 | C46: 65000 | D46: 브리니 | E46: 신한 | F46: ㈜브리니랩 | G46: ㅇ | H46: X
A47: 004 | B47: 34780104163197 | C47: 26000 | D47: 별대봉 | E47: 국민 | F47: ㈜투앤드컴퍼니 | G47: ㅇ | H47: X
A48: 007 | B48: 101023843370 | C48: 463650 | D48: 밤비 | E48: 수협 | F48: ㈜밤비컴퍼니 | G48: ㅇ | H48: O
A49: 088 | B49: 110489136548 | C49: 9000 | D49: 물고기 | E49: 신한 | F49: 블랙피쉬 | G49: ㅇ | H49: X
A50: 007 | B50: 101023336372 | C50: 24000 | D50: 몰핀 | E50: 수협 | F50: 이유진 | G50: ㅇ | H50: X
...

Sheet 1월24일
A1: ㅇ | B1: ㅇ | C1: ㅇ | D1: ㅇ | E1: ㅇ | F1: ㅇ | G1: ㅇ | H1: ㅇ
A2: 020 | B2: 1005504775443 | C2: 102000 | D2: 히피스 | E2: 우리 | F2: 이도영(히피스) | G2: ㅇ | H2: X
A3: 003 | B3: 20108343304014 | C3: 12000 | D3: 화이트옐로우 | E3: 기업 | F3: 옐로우이엔엠 주식회사 | G3: ㅇ | H3: X
A4: 020 | B4: 1005804834765 | C4: 18000 | D4: 홈런 | E4: 우리 | F4: ㈜플레이 홈런 | G4: ㅇ | H4: X
A5: 090 | B5: 3333289511795 | C5: 27000 | D5: 하이프 | E5: 카카오 | F5: 하이프(HYPE) | G5: ㅇ | H5: X
A6: 081 | B6: 17191028203607 | C6: 54000 | D6: 하이바 | E6: 하나 | F6: 김태형 | G6: ㅇ | H6: X
A7: 004 | B7: 80750104288480 | C7: 2879000 | D7: 필앤마조 | E7: 국민 | F7: (주)필앤마조 | G7: ㅇ | H7: X
A8: 003 | B8: 01041961598 | C8: 13000 | D8: 플레이 | E8: 기업 | F8: 김미라(플레이) | G8: ㅇ | H8: X
A9: 088 | B9: 140013540787 | C9: 124000 | D9: 풀하우스 | E9: 신한 | F9: 주식회사 풀하우스컴퍼니 김기완 | G9: ㅇ | H9: X
A10: 090 | B10: 3333123250772 | C10: 99000 | D10: 포레나 | E10: 카카오 | F10: 박진성 | G10: ㅇ | H10: X
A11: 088 | B11: 110316175919 | C11: 24000 | D11: 페어립트 | E11: 신한 | F11: 황두환(페어립트) | G11: ㅇ | H11: X
A12: 020 | B12: 1005602130034 | C12: 15000 | D12: 퍼블릭 | E12: 우리 | F12: ㈜진성 | G12: ㅇ | H12: X
A13: 088 | B13: 110555436511 | C13: 64000 | D13: 파인파인 | E13: 신한 | F13: 파인파인 | G13: ㅇ | H13: X
A14: 088 | B14: 140014915730 | C14: 160000 | D14: 티오 | E14: 신한 | F14: ㈜패션컴퍼니오성 | G14: ㅇ | H14: X
A15: 004 | B15: 34780104162710 | C15: 312000 | D15: 크레파스 | E15: 국민 | F15: ㈜투앤드컴퍼니 | G15: ㅇ | H15: X
A16: 081 | B16: 28491002673804 | C16: 609400 | D16: 코디63 | E16: 하나 | F16: ㈜코디63 | G16: ㅇ | H16: O
A17: 020 | B17: 35007115702103 | C17: 6000 | D17: 케이스타 | E17: 우리 | F17: 임미선 | G17: ㅇ | H17: X
A18: 003 | B18: 01500000197711 | C18: 381700 | D18: 케이디지 | E18: 기업 | F18: 케이디지 | G18: ㅇ | H18: O
A19: 004 | B19: 77463704004031 | C19: 56000 | D19: 줄리 | E19: 국민 | F19: ㈜쥴리 | G19: ㅇ | H19: X
A20: 081 | B20: 13502366500508 | C20: 42000 | D20: 제이케이 | E20: 하나 | F20: 김진규 | G20: ㅇ | H20: X
A21: 004 | B21: 09340104281400 | C21: 110500 | D21: 제이원 | E21: 국민 | F21: 이경목(제이원) | G21: ㅇ | H21: X
A22: 020 | B22: 1005404757533 | C22: 10000 | D22: 제니퍼 | E22: 우리 | F22: 김미애(제니퍼) | G22: ㅇ | H22: X
A23: 081 | B23: 28191003840204 | C23: 128000 | D23: 저기 | E23: 하나 | F23: 에브리웨어 | G23: ㅇ | H23: X
A24: 003 | B24: 08606527904019 | C24: 25000 | D24: 일프로 | E24: 기업 | F24: ㈜더일프로 | G24: ㅇ | H24: X
A25: 003 | B25: 08606354904011 | C25: 14000 | D25: 이퓨 | E25: 기업 | F25: ㈜티센 | G25: ㅇ | H25: X
A26: 081 | B26: 21891004070404 | C26: 12000 | D26: 이안 | E26: 하나 | F26: 주식회사 데이앤 | G26: ㅇ | H26: X
A27: 081 | B27: 19991017546307 | C27: 128000 | D27: 이사벨라 | E27: 하나 | F27: 조휘호 | G27: ㅇ | H27: X
A28: 088 | B28: 110565571708 | C28: 10000 | D28: 유에이드 | E28: 신한 | F28: 유에이드(정연화) | G28: ㅇ | H28: X
A29: 004 | B29: 00570104181266 | C29: 9000 | D29: 유스픽 | E29: 국민 | F29: 유성진 | G29: ㅇ | H29: X
... A31: 020 | B31: 1005404565023 | C31: 24750 | D31: 유돈노미 | E31: 우리 | F31: 유돈노미 | G31: ㅇ | H31: X
A32: 090 | B32: 3333267395045 | C32: 25000 | D32: 유니모어 | E32: 카카오 | F32: 이석일(유니모어) | G32: ㅇ | H32: x
A33: 004 | B33: 17130104207865 | C33: 34000 | D33: 윌 | E33: 국민 | F33: 김성희(윌) | G33: ㅇ | H33: X
A34: 081 | B34: 22191002103004 | C34: 339900 | D34: 위클리 | E34: 하나 | F34: 주식회사제이와이글로벌패션그룹 | G34: ㅇ | H34: O
A35: 020 | B35: 1005104702925 | C35: 40000 | D35: 우트 | E35: 우리 | F35: ㈜오오티제이 오리진 | G35: ㅇ | H35: O
A36: 088 | B36: 140012598030 | C36: 36300 | D36: 오즈브릿지 | E36: 신한 | F36: ㈜오즈브릿지 | G36: ㅇ | H36: X
A37: 003 | B37: 08606445401018 | C37: 28000 | D37: 오드블루 | E37: 기업 | F37: 이성현 | G37: ㅇ | H37: X
A38: 088 | B38: 140015691630 | C38: 137500 | D38: 오드 | E38: 신한 | F38: 주식회사 오드점 | G38: ㅇ | H38: X
A39: 003 | B39: 20107648001016 | C39: 15000 | D39: 옐로우 | E39: 기업 | F39: 옐로우이엔엠 주식회사 | G39: ㅇ | H39: X
A40: 020 | B40: 1005504495386 | C40: 180000 | D40: 여기 | E40: 우리 | F40: 에브리웨어 | G40: ㅇ | H40: X
A41: 088 | B41: 140013987091 | C41: 110000 | D41: 엣지 | E41: 신한 | F41: ㈜이디지이(EDGE) | G41: ㅇ | H41: X
...

Sheet 1월27일
A1: ㅇ | B1: ㅇ | C1: ㅇ | D1: ㅇ | E1: ㅇ | F1: ㅇ | G1: ㅇ | H1: ㅇ
A2: 020 | B2: 1005603106537 | C2: 405000 | D2: 힙블리 | E2: 우리 | F2: 오승미 | G2: ㅇ | H2: x
A3: 020 | B3: 1005403055136 | C3: 10000 | D3: 허밍마켓 | E3: 우리 | F3: 허밍마켓 | G3: ㅇ | H3: X
A4: 090 | B4: 3333289511795 | C4: 12000 | D4: 하이프 | E4: 카카오 | F4: 하이프(HYPE) | G4: ㅇ | H4: X
A5: 088 | B5: 110554774968 | C5: 18000 | D5: 하이앤땡큐 | E5: 신한 | F5: 김승현 | G5: ㅇ | H5: X
A6: 081 | B6: 17191028203607 | C6: 9000 | D6: 하이바 | E6: 하나 | F6: 김태형 | G6: ㅇ | H6: X
A7: 004 | B7: 09180104175091 | C7: 20000 | D7: 하멜 | E7: 국민 | F7: 우환균(하멜) | G7: ㅇ | H7: X
A8: 004 | B8: 79660104124093 | C8: 38000 | D8: 하루하 | E8: 국민 | F8: 하루하 | G8: ㅇ | H8: X
A9: 004 | B9: 80750104288480 | C9: 9000 | D9: 필앤마조 | E9: 국민 | F9: (주)필앤마조 | G9: ㅇ | H9: X
A10: 088 | B10: 110604500814 | C10: 35000 | D10: 피크닉 | E10: 신한 | F10: 피크닉 | G10: ㅇ | H10: X
A11: 088 | B11: 140013540787 | C11: 42000 | D11: 풀하우스 | E11: 신한 | F11: 주식회사 풀하우스컴퍼니 김기완 | G11: ㅇ | H11: X
A12: 004 | B12: 79660104121302 | C12: 21000 | D12: 푸딩 | E12: 국민 | F12: 박혜민 | G12: ㅇ | H12: X
A13: 090 | B13: 3333123250772 | C13: 18000 | D13: 포레나 | E13: 카카오 | F13: 박진성 | G13: ㅇ | H13: X
A14: 003 | B14: 01819320404015 | C14: 6600 | D14: 퍼플그레이 | E14: 기업 | F14: ㈜퍼플그레이어패럴 | G14: ㅇ | H14: O
A15: 020 | B15: 1005603272336 | C15: 36000 | D15: 트웬티 | E15: 우리 | F15: 이한숙 | G15: ㅇ | H15: X
A16: 011 | B16: 3022043205911 | C16: 37500 | D16: 투썸 | E16: 농협 | F16: 투썸 | G16: ㅇ | H16: X
A17: 003 | B17: 01212165604012 | C17: 825000 | D17: 크림베이지 | E17: 기업 | F17: 주식회사 크림베이지어패럴 | G17: ㅇ | H17: O
A18: 004 | B18: 34780104162710 | C18: 135000 | D18: 크레파스 | E18: 국민 | F18: ㈜투앤드컴퍼니 | G18: ㅇ | H18: X
A19: 081 | B19: 28491002673804 | C19: 1080200 | D19: 코디63 | E19: 하나 | F19: ㈜코디63 | G19: ㅇ | H19: O
A20: 003 | B20: 01500000197711 | C20: 175450 | D20: 케이디지 | E20: 기업 | F20: 케이디지 | G20: ㅇ | H20: O
A21: 088 | B21: 140012386934 | C21: 12000 | D21: 지엔 | E21: 신한 | F21: ㈜지엔어패럴 | G21: ㅇ | H21: X
A22: 004 | B22: 77463704004031 | C22: 31000 | D22: 줄리 | E22: 국민 | F22: ㈜쥴리 | G22: ㅇ | H22: X
A23: 020 | B23: 1005903426037 | C23: 7700 | D23: 제이덕 | E23: 우리 | F23: ㈜에이치케이더블류컴퍼니 | G23: ㅇ | H23: O
A24: 081 | B24: 28191003840204 | C24: 10000 | D24: 저기 | E24: 하나 | F24: 에브리웨어 | G24: ㅇ | H24: X
A25: 003 | B25: 08606527904019 | C25: 7000 | D25: 일프로 | E25: 기업 | F25: ㈜더일프로 | G25: ㅇ | H25: X
A26: 004 | B26: 05103704007672 | C26: 20000 | D26: 이향 | E26: 국민 | F26: 장소영 | G26: ㅇ | H26: X
A27: 081 | B27: 19991017546307 | C27: 106000 | D27: 이사벨라 | E27: 하나 | F27: 조휘호 | G27: ㅇ | H27: X
A28: 081 | B28: 27991001398304 | C28: 92000 | D28: 이고 | E28: 하나 | F28: 더원컴퍼니 | G28: ㅇ | H28: X
A29: 004 | B29: 00570104181266 | C29: 9000 | D29: 유스픽 | E29: 국민 | F29: 유성진 | G29: ㅇ | H29: X
A30: 088 | B30: 110224033860 | C30: 36000 | D30: 유리 | E30: 신한 | F30: 박성은 | G30: ㅇ | H30: X
A31: 090 | B31: 3333267395045 | C31: 12000 | D31: 유니모어 | E31: 카카오 | F31: 이석일(유니모어) | G31: ㅇ | H31: x
A32: 004 | B32: 17130104207865 | C32: 51000 | D32: 윌 | E32: 국민 | F32: 김성희(윌) | G32: ㅇ | H32: X
A33: 081 | B33: 22191002103004 | C33: 239800 | D33: 위클리 | E33: 하나 | F33: 주식회사제이와이글로벌패션그룹 | G33: ㅇ | H33: O
A34: 088 | B34: 110367521470 | C34: 1567000 | D34: 요미요미 | E34: 신한 | F34: 이정규(요미요미) | G34: ㅇ | H34: X
A35: 088 | B35: 140012598030 | C35: 18700 | D35: 오즈브릿지 | E35: 신한 | F35: ㈜오즈브릿지 | G35: ㅇ | H35: X
A36: 088 | B36: 140015691630 | C36: 13500 | D36: 오드 | E36: 신한 | F36: 주식회사 오드점 | G36: ㅇ | H36: X
A37: 088 | B37: 110555467484 | C37: 62000 | D37: 오도시 | E37: 신한 | F37: 임창현/오도시 | G37: ㅇ | H37: X
A38: 020 | B38: 1005504495386 | C38: 132000 | D38: 여기 | E38: 우리 | F38: 에브리웨어 | G38: ㅇ | H38: X
A39: 088 | B39: 110517059780 | C39: 42900 | D39: 엔초 | E39: 신한 | F39: 최훈정(엔초) | G39: ㅇ | H39: O
A40: 088 | B40: 110539887153 | C40: 149000 | D40: 안나 | E40: 신한 | F40: 김수진 | G40: ㅇ | H40: X
...

Sheet 1월 28일
A1: ㅇ | B1: ㅇ | C1: ㅇ | D1: ㅇ | E1: ㅇ | F1: ㅇ | G1: ㅇ | H1: ㅇ
A2: 020 | B2: 1005603106537 | C2: 24000 | D2: 힙블리 | E2: 우리 | F2: 오승미 | G2: ㅇ | H2: x
A3: 020 | B3: 1005504775443 | C3: 96000 | D3: 히피스 | E3: 우리 | F3: 이도영(히피스) | G3: ㅇ | H3: X
A4: 003 | B4: 35611228204015 | C4: 12000 | D4: 호스피텔로비 | E4: 기업 | F4: 김근량 | G4: ㅇ | H4: X
A5: 081 | B5: 17191028203607 | C5: 18000 | D5: 하이바 | E5: 하나 | F5: 김태형 | G5: ㅇ | H5: X
A6: 004 | B6: 80750104288480 | C6: 7175000 | D6: 필앤마조 | E6: 국민 | F6: (주)필앤마조 | G6: ㅇ | H6: X
A7: 088 | B7: 110604500814 | C7: 7000 | D7: 피크닉 | E7: 신한 | F7: 피크닉 | G7: ㅇ | H7: X
A8: 004 | B8: 07300104259173 | C8: 1300000 | D8: 프레쩰 | E8: 국민 | F8: 주현 | G8: ㅇ | H8: X
A9: 088 | B9: 140013540787 | C9: 70000 | D9: 풀하우스 | E9: 신한 | F9: 주식회사 풀하우스컴퍼니 김기완 | G9: ㅇ | H9: X
A10: 088 | B10: 110316175919 | C10: 120000 | D10: 페어립트 | E10: 신한 | F10: 황두환(페어립트) | G10: ㅇ | H10: X
A11: 088 | B11: 110564250069 | C11: 7000 | D11: 펀치 | E11: 신한 | F11: 양창민(펀치) | G11: ㅇ | H11: X
A12: 003 | B12: 01819320404015 | C12: 4400 | D12: 퍼플그레이 | E12: 기업 | F12: ㈜퍼플그레이어패럴 | G12: ㅇ | H12: O
A13: 020 | B13: 1005602130034 | C13: 30000 | D13: 퍼블릭 | E13: 우리 | F13: ㈜진성 | G13: ㅇ | H13: X
A14: 088 | B14: 110555436511 | C14: 200000 | D14: 파인파인 | E14: 신한 | F14: 파인파인 | G14: ㅇ | H14: X
A15: 088 | B15: 140014915730 | C15: 30000 | D15: 티오 | E15: 신한 | F15: ㈜패션컴퍼니오성 | G15: ㅇ | H15: X
A16: 011 | B16: 3022043205911 | C16: 25000 | D16: 투썸 | E16: 농협 | F16: 투썸 | G16: ㅇ | H16: X
A17: 004 | B17: 34780104162710 | C17: 99000 | D17: 크레파스 | E17: 국민 | F17: ㈜투앤드컴퍼니 | G17: ㅇ | H17: X
A18: 081 | B18: 28491002673804 | C18: 2730200 | D18: 코디63 | E18: 하나 | F18: ㈜코디63 | G18: ㅇ | H18: O
A19: 003 | B19: 01500000197711 | C19: 386650 | D19: 케이디지 | E19: 기업 | F19: 케이디지 | G19: ㅇ | H19: O
A20: 020 | B20: 1005003797667 | C20: 495000 | D20: 컴온 | E20: 우리 | F20: ㈜에이치케이더블류컴퍼니 | G20: ㅇ | H20: X
A21: 004 | B21: 59280104131903 | C21: 493000 | D21: 치퍼 | E21: 국민 | F21: 최현준(치퍼(CHIPPER)) | G21: ㅇ | H21: X
A22: 003 | B22: 50003222004019 | C22: 44000 | D22: 진머니 | E22: 기업 | F22: ㈜진머니 | G22: ㅇ | H22: O
A23: 088 | B23: 140012386934 | C23: 96000 | D23: 지엔 | E23: 신한 | F23: ㈜지엔어패럴 | G23: ㅇ | H23: X
A24: 004 | B24: 79660104099780 | C24: 30000 | D24: 제임스 | E24: 국민 | F24: ㈜더블유에이치컴퍼니 | G24: ㅇ | H24: X
A25: 081 | B25: 13502366500508 | C25: 42000 | D25: 제이케이 | E25: 하나 | F25: 김진규 | G25: ㅇ | H25: X
A26: 020 | B26: 1005704050928 | C26: 7500 | D26: 저지방 | E26: 우리 | F26: ㈜드레스코코 | G26: ㅇ | H26: X
A27: 081 | B27: 28191003840204 | C27: 8000 | D27: 저기 | E27: 하나 | F27: 에브리웨어 | G27: ㅇ | H27: X
A28: 003 | B28: 08606527904019 | C28: 49000 | D28: 일프로 | E28: 기업 | F28: ㈜더일프로 | G28: ㅇ | H28: X
A29: 004 | B29: 05103704007672 | C29: 10000 | D29: 이향 | E29: 국민 | F29: 장소영 | G29: ㅇ | H29: X
... A33: 020 | B33: 1005404565023 | C33: 22500 | D33: 유돈노미 | E33: 우리 | F33: 유돈노미 | G33: ㅇ | H33: X
A34: 090 | B34: 3333267395045 | C34: 12000 | D34: 유니모어 | E34: 카카오 | F34: 이석일(유니모어) | G34: ㅇ | H34: x
A35: 081 | B35: 22191002103004 | C35: 238700 | D35: 위클리 | E35: 하나 | F35: 주식회사제이와이글로벌패션그룹 | G35: ㅇ | H35: O
A36: 088 | B36: 140012598030 | C36: 15400 | D36: 오즈브릿지 | E36: 신한 | F36: ㈜오즈브릿지 | G36: ㅇ | H36: X
A37: 088 | B37: 140015691630 | C37: 50000 | D37: 오드 | E37: 신한 | F37: 주식회사 오드점 | G37: ㅇ | H37: X
A38: 020 | B38: 1005504495386 | C38: 22000 | D38: 여기 | E38: 우리 | F38: 에브리웨어 | G38: ㅇ | H38: X
A39: 088 | B39: 140013987091 | C39: 100000 | D39: 엣지 | E39: 신한 | F39: ㈜이디지이(EDGE) | G39: ㅇ | H39: X
A40: 088 | B40: 110425567853 | C40: 20000 | D40: 엘로즈 | E40: 신한 | F40: 이현승엘로즈 | G40: ㅇ | H40: X
A41: 088 | B41: 110539887153 | C41: 41000 | D41: 안나 | E41: 신한 | F41: 김수진 | G41: ㅇ | H41: X
A42: 020 | B42: 1005203796625 | C42: 537000 | D42: 아이티 | E42: 우리 | F42: HKW컴퍼니 | G42: ㅇ | H42: X
A43: 088 | B43: 100031465474 | C43: 28000 | D43: 아가씨 | E43: 신한 | F43: 이성현 | G43: ㅇ | H43: X
...

Sheet 1월 29일
A1: ㅇ | B1: ㅇ | C1: ㅇ | D1: ㅇ | E1: ㅇ | F1: ㅇ | G1: ㅇ | H1: ㅇ
A2: 081 | B2: 17191028203607 | C2: 18000 | D2: 하이바 | E2: 하나 | F2: 김태형 | G2: ㅇ | H2: X
A3: 004 | B3: 80750104288480 | C3: 8815000 | D3: 필앤마조 | E3: 국민 | F3: (주)필앤마조 | G3: ㅇ | H3: X
A4: 004 | B4: 80750104288480 | C4: 2870000 | D4: 필앤마조 | E4: 국민 | F4: (주)필앤마조 | G4: ㅇ | H4: X
A5: 088 | B5: 110604500814 | C5: 7000 | D5: 피크닉 | E5: 신한 | F5: 피크닉 | G5: ㅇ | H5: X
A6: 088 | B6: 140013540787 | C6: 28000 | D6: 풀하우스 | E6: 신한 | F6: 주식회사 풀하우스컴퍼니 김기완 | G6: ㅇ | H6: X
A7: 004 | B7: 79660104121302 | C7: 7000 | D7: 푸딩 | E7: 국민 | F7: 박혜민 | G7: ㅇ | H7: X
A8: 090 | B8: 3333123250772 | C8: 99000 | D8: 포레나 | E8: 카카오 | F8: 박진성 | G8: ㅇ | H8: X
A9: 088 | B9: 110316175919 | C9: 48000 | D9: 페어립트 | E9: 신한 | F9: 황두환(페어립트) | G9: ㅇ | H9: X
A10: 088 | B10: 110564250069 | C10: 7000 | D10: 펀치 | E10: 신한 | F10: 양창민(펀치) | G10: ㅇ | H10: X
A11: 003 | B11: 01819320404015 | C11: 4400 | D11: 퍼플그레이 | E11: 기업 | F11: ㈜퍼플그레이어패럴 | G11: ㅇ | H11: O
A12: 088 | B12: 110555436511 | C12: 26000 | D12: 파인파인 | E12: 신한 | F12: 파인파인 | G12: ㅇ | H12: X
A13: 088 | B13: 140014915730 | C13: 312000 | D13: 티오 | E13: 신한 | F13: ㈜패션컴퍼니오성 | G13: ㅇ | H13: X
A14: 020 | B14: 1005603272336 | C14: 12000 | D14: 트웬티 | E14: 우리 | F14: 이한숙 | G14: ㅇ | H14: X
A15: 004 | B15: 34780104162710 | C15: 42000 | D15: 크레파스 | E15: 국민 | F15: ㈜투앤드컴퍼니 | G15: ㅇ | H15: X
A16: 003 | B16: 01500000197711 | C16: 234300 | D16: 케이디지 | E16: 기업 | F16: 케이디지 | G16: ㅇ | H16: O
A17: 004 | B17: 59280104131903 | C17: 22000 | D17: 치퍼 | E17: 국민 | F17: 최현준(치퍼(CHIPPER)) | G17: ㅇ | H17: X
A18: 003 | B18: 01211719604010 | C18: 9000 | D18: 주식회사티야 | E18: 기업 | F18: 주식회사 티야 | G18: ㅇ | H18: x
A19: 081 | B19: 13502366500508 | C19: 21000 | D19: 제이케이 | E19: 하나 | F19: 김진규 | G19: ㅇ | H19: X
A20: 004 | B20: 09340104281400 | C20: 102000 | D20: 제이원 | E20: 국민 | F20: 이경목(제이원) | G20: ㅇ | H20: X
... A25: 081 | B25: 39091033424807 | C25: 12000 | D25: 유스 | E25: 하나 | F25: 최민준(유스) | G25: ㅇ | H25: X
A26: 090 | B26: 3333267395045 | C26: 12000 | D26: 유니모어 | E26: 카카오 | F26: 이석일(유니모어) | G26: ㅇ | H26: x
A27: 081 | B27: 22191002103004 | C27: 325600 | D27: 위클리 | E27: 하나 | F27: 주식회사제이와이글로벌패션그룹 | G27: ㅇ | H27: O
A28: 088 | B28: 110367521470 | C28: 1301000 | D28: 요미요미 | E28: 신한 | F28: 이정규(요미요미) | G28: ㅇ | H28: X
A29: 088 | B29: 110474414886 | C29: 19000 | D29: 와이파이 | E29: 신한 | F29: 김예근(WIFI) | G29: ㅇ | H29: X
A30: 004 | B30: 05070104126403 | C30: 24000 | D30: 옥수수 | E30: 국민 | F30: 김민식 | G30: ㅇ | H30: X
A31: 088 | B31: 140012598030 | C31: 20350 | D31: 오즈브릿지 | E31: 신한 | F31: ㈜오즈브릿지 | G31: ㅇ | H31: X
A32: 088 | B32: 140015691630 | C32: 49000 | D32: 오드 | E32: 신한 | F32: 주식회사 오드점 | G32: ㅇ | H32: X
A33: 003 | B33: 20107648001016 | C33: 15000 | D33: 옐로우 | E33: 기업 | F33: 옐로우이엔엠 주식회사 | G33: ㅇ | H33: X
A34: 020 | B34: 1005504495386 | C34: 32000 | D34: 여기 | E34: 우리 | F34: 에브리웨어 | G34: ㅇ | H34: X
A35: 088 | B35: 140013987091 | C35: 12000 | D35: 엣지 | E35: 신한 | F35: ㈜이디지이(EDGE) | G35: ㅇ | H35: X
A36: 020 | B36: 1005804294993 | C36: 9000 | D36: 얼리모닝 | E36: 우리 | F36: 백승갑 | G36: ㅇ | H36: X
A37: 088 | B37: 110539887153 | C37: 164000 | D37: 안나 | E37: 신한 | F37: 김수진 | G37: ㅇ | H37: X
A38: 004 | B38: 40913701004859 | C38: 10000 | D38: 아페리얼 | E38: 국민 | F38: ㈜아페리얼 | G38: ㅇ | H38: X
A39: 020 | B39: 1005203796625 | C39: 658000 | D39: 아이티 | E39: 우리 | F39: HKW컴퍼니 | G39: ㅇ | H39: X
A40: 088 | B40: 110564935137 | C40: 10000 | D40: 스크램블 | E40: 신한 | F40: 스크램블 | G40: ㅇ | H40: X
A41: 081 | B41: 38891000310908 | C41: 183000 | D41: 슈퍼스타 | E41: 하나 | F41: 김학영 | G41: ㅇ | H41: X
A42: 088 | B42: 140014903450 | C42: 27000 | D42: 슈퍼땅콩 | E42: 신한 | F42: 슈퍼땅콩 | G42: ㅇ | H42: X
A43: 088 | B43: 110196330916 | C43: 15000 | D43: 솜솜 | E43: 신한 | F43: 장애리 | G43: ㅇ | H43: X
A44: 081 | B44: 20791052452207 | C44: 40000 | D44: 뿌 | E44: 하나 | F44: 이준미 | G44: ㅇ | H44: X
...

Sheet 1월 30일
A1: ㅇ | B1: ㅇ | C1: ㅇ | D1: ㅇ | E1: ㅇ | F1: ㅇ | G1: ㅇ | H1: ㅇ
A2: {=INDEX(은행코드!$B$1:$B$24,MATCH(E2,은행코드!$A$1:$A$24,0),0)} -> 020 | B2: {=INDEX(Sheet1!$B$2:$B$9999,MATCH(D2,Sheet1!$D$2:$D$9999,0),0)} -> 1005504775443 | C2: 96000 | D2: 히피스 | E2: {=INDEX(Sheet1!$E$2:$E$9999,MATCH(D2,Sheet1!$D$2:$D$9999,0),0)} -> 우리 | F2: {=INDEX(Sheet1!$F$2:$F$9999,MATCH(D2,Sheet1!$D$2:$D$9999,0),0)} -> 이도영(히피스) | G2: ㅇ | H2: {=INDEX(Sheet1!$H$2:$H$9999,MATCH(D2,Sheet1!$D$2:$D$9999,0),0)} -> X
A3: {=INDEX(은행코드!$B$1:$B$24,MATCH(E3,은행코드!$A$1:$A$24,0),0)} -> 020 | B3: {=INDEX(Sheet1!$B$2:$B$9999,MATCH(D3,Sheet1!$D$2:$D$9999,0),0)} -> 1005804834765 | C3: 9000 | D3: 홈런 | E3: {=INDEX(Sheet1!$E$2:$E$9999,MATCH(D3,Sheet1!$D$2:$D$9999,0),0)} -> 우리 | F3: {=INDEX(Sheet1!$F$2:$F$9999,MATCH(D3,Sheet1!$D$2:$D$9999,0),0)} -> ㈜플레이 홈런 | G3: ㅇ | H3: {=INDEX(Sheet1!$H$2:$H$9999,MATCH(D3,Sheet1!$D$2:$D$9999,0),0)} -> X
A4: {=INDEX(은행코드!$B$1:$B$24,MATCH(E4,은행코드!$A$1:$A$24,0),0)} -> 090 | B4: {=INDEX(Sheet1!$B$2:$B$9999,MATCH(D4,Sheet1!$D$2:$D$9999,0),0)} -> 3333289511795 | C4: 116000 | D4: 하이프 | E4: {=INDEX(Sheet1!$E$2:$E$9999,MATCH(D4,Sheet1!$D$2:$D$9999,0),0)} -> 카카오 | F4: {=INDEX(Sheet1!$F$2:$F$9999,MATCH(D4,Sheet1!$D$2:$D$9999,0),0)} -> 하이프(HYPE) | G4: ㅇ | H4: {=INDEX(Sheet1!$H$2:$H$9999,MATCH(D4,Sheet1!$D$2:$D$9999,0),0)} -> X
A5: {=INDEX(은행코드!$B$1:$B$24,MATCH(E5,은행코드!$A$1:$A$24,0),0)} -> 088 | B5: {=INDEX(Sheet1!$B$2:$B$9999,MATCH(D5,Sheet1!$D$2:$D$9999,0),0)} -> 110554774968 | C5: 36000 | D5: 하이앤땡큐 | E5: {=INDEX(Sheet1!$E$2:$E$9999,MATCH(D5,Sheet1!$D$2:$D$9999,0),0)} -> 신한 | F5: {=INDEX(Sheet1!$F$2:$F$9999,MATCH(D5,Sheet1!$D$2:$D$9999,0),0)} -> 김승현 | G5: ㅇ | H5: {=INDEX(Sheet1!$H$2:$H$9999,MATCH(D5,Sheet1!$D$2:$D$9999,0),0)} -> X
A6: {=INDEX(은행코드!$B$1:$B$24,MATCH(E6,은행코드!$A$1:$A$24,0),0)} -> 081 | B6: {=INDEX(Sheet1!$B$2:$B$9999,MATCH(D6,Sheet1!$D$2:$D$9999,0),0)} -> 17191028203607 | C6: 54000 | D6: 하이바 | E6: {=INDEX(Sheet1!$E$2:$E$9999,MATCH(D6,Sheet1!$D$2:$D$9999,0),0)} -> 하나 | F6: {=INDEX(Sheet1!$F$2:$F$9999,MATCH(D6,Sheet1!$D$2:$D$9999,0),0)} -> 김태형 | G6: ㅇ | H6: {=INDEX(Sheet1!$H$2:$H$9999,MATCH(D6,Sheet1!$D$2:$D$9999,0),0)} -> X
A7: {=INDEX(은행코드!$B$1:$B$24,MATCH(E7,은행코드!$A$1:$A$24,0),0)} -> 004 | B7: {=INDEX(Sheet1!$B$2:$B$9999,MATCH(D7,Sheet1!$D$2:$D$9999,0),0)} -> 80750104288480 | C7: 20500 | D7: 필앤마조 | E7: {=INDEX(Sheet1!$E$2:$E$9999,MATCH(D7,Sheet1!$D$2:$D$9999,0),0)} -> 국민 | F7: {=INDEX(Sheet1!$F$2:$F$9999,MATCH(D7,Sheet1!$D$2:$D$9999,0),0)} -> (주)필앤마조 | G7: ㅇ | H7: {=INDEX(Sheet1!$H$2:$H$9999,MATCH(D7,Sheet1!$D$2:$D$9999,0),0)} -> X
A8: {=INDEX(은행코드!$B$1:$B$24,MATCH(E8,은행코드!$A$1:$A$24,0),0)} -> 004 | B8: {=INDEX(Sheet1!$B$2:$B$9999,MATCH(D8,Sheet1!$D$2:$D$9999,0),0)} -> 07300104259173 | C8: 208000 | D8: 프레쩰 | E8: {=INDEX(Sheet1!$E$2:$E$9999,MATCH(D8,Sheet1!$D$2:$D$9999,0),0)} -> 국민 | F8: {=INDEX(Sheet1!$F$2:$F$9999,MATCH(D8,Sheet1!$D$2:$D$9999,0),0)} -> 주현 | G8: ㅇ | H8: {=INDEX(Sheet1!$H$2:$H$9999,MATCH(D8,Sheet1!$D$2:$D$9999,0),0)} -> X
A9: {=INDEX(은행코드!$B$1:$B$24,MATCH(E9,은행코드!$A$1:$A$24,0),0)} -> 003 | B9: {=INDEX(Sheet1!$B$2:$B$9999,MATCH(D9,Sheet1!$D$2:$D$9999,0),0)} -> 01819320404015 | C9: 31350 | D9: 퍼플그레이 | E9: {=INDEX(Sheet1!$E$2:$E$9999,MATCH(D9,Sheet1!$D$2:$D$9999,0),0)} -> 기업 | F9: {=INDEX(Sheet1!$F$2:$F$9999,MATCH(D9,Sheet1!$D$2:$D$9999,0),0)} -> ㈜퍼플그레이어패럴 | G9: ㅇ | H9: {=INDEX(Sheet1!$H$2:$H$9999,MATCH(D9,Sheet1!$D$2:$D$9999,0),0)} -> O
A10: {=INDEX(은행코드!$B$1:$B$24,MATCH(E10,은행코드!$A$1:$A$24,0),0)} -> 088 | B10: {=INDEX(Sheet1!$B$2:$B$9999,MATCH(D10,Sheet1!$D$2:$D$9999,0),0)} -> 110555436511 | C10: 50000 | D10: 파인파인 | E10: {=INDEX(Sheet1!$E$2:$E$9999,MATCH(D10,Sheet1!$D$2:$D$9999,0),0)} -> 신한 | F10: {=INDEX(Sheet1!$F$2:$F$9999,MATCH(D10,Sheet1!$D$2:$D$9999,0),0)} -> 파인파인 | G10: ㅇ | H10: {=INDEX(Sheet1!$H$2:$H$9999,MATCH(D10,Sheet1!$D$2:$D$9999,0),0)} -> X
A11: {=INDEX(은행코드!$B$1:$B$24,MATCH(E11,은행코드!$A$1:$A$24,0),0)} -> 088 | B11: {=INDEX(Sheet1!$B$2:$B$9999,MATCH(D11,Sheet1!$D$2:$D$9999,0),0)} -> 140014915730 | C11: 306000 | D11: 티오 | E11: {=INDEX(Sheet1!$E$2:$E$9999,MATCH(D11,Sheet1!$D$2:$D$9999,0),0)} -> 신한 | F11: {=INDEX(Sheet1!$F$2:$F$9999,MATCH(D11,Sheet1!$D$2:$D$9999,0),0)} -> ㈜패션컴퍼니오성 | G11: ㅇ | H11: {=INDEX(Sheet1!$H$2:$H$9999,MATCH(D11,Sheet1!$D$2:$D$9999,0),0)} -> X
A12: {=INDEX(은행코드!$B$1:$B$24,MATCH(E12,은행코드!$A$1:$A$24,0),0)} -> 011 | B12: {=INDEX(Sheet1!$B$2:$B$9999,MATCH(D12,Sheet1!$D$2:$D$9999,0),0)} -> 3022043205911 | C12: 62500 | D12: 투썸 | E12: {=INDEX(Sheet1!$E$2:$E$9999,MATCH(D12,Sheet1!$D$2:$D$9999,0),0)} -> 농협 | F12: {=INDEX(Sheet1!$F$2:$F$9999,MATCH(D12,Sheet1!$D$2:$D$9999,0),0)} -> 투썸 | G12: ㅇ | H12: {=INDEX(Sheet1!$H$2:$H$9999,MATCH(D12,Sheet1!$D$2:$D$9999,0),0)} -> X
A13: {=INDEX(은행코드!$B$1:$B$24,MATCH(E13,은행코드!$A$1:$A$24,0),0)} -> 003 | B13: {=INDEX(Sheet1!$B$2:$B$9999,MATCH(D13,Sheet1!$D$2:$D$9999,0),0)} -> 01212165604012 | C13: 371250 | D13: 크림베이지 | E13: {=INDEX(Sheet1!$E$2:$E$9999,MATCH(D13,Sheet1!$D$2:$D$9999,0),0)} -> 기업 | F13: {=INDEX(Sheet1!$F$2:$F$9999,MATCH(D13,Sheet1!$D$2:$D$9999,0),0)} -> 주식회사 크림베이지어패럴 | G13: ㅇ | H13: {=INDEX(Sheet1!$H$2:$H$9999,MATCH(D13,Sheet1!$D$2:$D$9999,0),0)} -> O
... A58: {=INDEX(은행코드!$B$1:$B$24,MATCH(E58,은행코드!$A$1:$A$24,0),0)} -> 020 | B58: {=INDEX(Sheet1!$B$2:$B$9999,MATCH(D58,Sheet1!$D$2:$D$9999,0),0)} -> 1005902745135 | C58: 37000 | D58: 멋쟁이 | E58: {=INDEX(Sheet1!$E$2:$E$9999,MATCH(D58,Sheet1!$D$2:$D$9999,0),0)} -> 우리 | F58: {=INDEX(Sheet1!$F$2:$F$9999,MATCH(D58,Sheet1!$D$2:$D$9999,0),0)} -> 김덕영 | G58: ㅇ | H58: {=INDEX(Sheet1!$H$2:$H$9999,MATCH(D58,Sheet1!$D$2:$D$9999,0),0)} -> X
A59: {=INDEX(은행코드!$B$1:$B$24,MATCH(E59,은행코드!$A$1:$A$24,0),0)} -> 088 | B59: 140012077981 | C59: 5000 | D59: 마이티 | E59: 신한 | F59: ㈜마이마이티 | G59: ㅇ | H59: X
A60: {=INDEX(은행코드!$B$1:$B$24,MATCH(E60,은행코드!$A$1:$A$24,0),0)} -> 003 | B60: {=INDEX(Sheet1!$B$2:$B$9999,MATCH(D60,Sheet1!$D$2:$D$9999,0),0)} -> 91702676804019 | C60: 474650 | D60: 리자드스탠다드 | E60: {=INDEX(Sheet1!$E$2:$E$9999,MATCH(D60,Sheet1!$D$2:$D$9999,0),0)} -> 기업 | F60: {=INDEX(Sheet1!$F$2:$F$9999,MATCH(D60,Sheet1!$D$2:$D$9999,0),0)} -> 리자드스탠다드 | G60: ㅇ | H60: {=INDEX(Sheet1!$H$2:$H$9999,MATCH(D60,Sheet1!$D$2:$D$9999,0),0)} -> O
A61: {=INDEX(은행코드!$B$1:$B$24,MATCH(E61,은행코드!$A$1:$A$24,0),0)} -> 088 | B61: {=INDEX(Sheet1!$B$2:$B$9999,MATCH(D61,Sheet1!$D$2:$D$9999,0),0)} -> 140015690682 | C61: 18150 | D61: 리디아 | E61: {=INDEX(Sheet1!$E$2:$E$9999,MATCH(D61,Sheet1!$D$2:$D$9999,0),0)} -> 신한 | F61: {=INDEX(Sheet1!$F$2:$F$9999,MATCH(D61,Sheet1!$D$2:$D$9999,0),0)} -> ㈜리디아컴퍼니 | G61: ㅇ | H61: {=INDEX(Sheet1!$H$2:$H$9999,MATCH(D61,Sheet1!$D$2:$D$9999,0),0)} -> O
A62: {=INDEX(은행코드!$B$1:$B$24,MATCH(E62,은행코드!$A$1:$A$24,0),0)} -> 004 | B62: {=INDEX(Sheet1!$B$2:$B$9999,MATCH(D62,Sheet1!$D$2:$D$9999,0),0)} -> 03610104060011 | C62: 36000 | D62: 루나 | E62: {=INDEX(Sheet1!$E$2:$E$9999,MATCH(D62,Sheet1!$D$2:$D$9999,0),0)} -> 국민 | F62: {=INDEX(Sheet1!$F$2:$F$9999,MATCH(D62,Sheet1!$D$2:$D$9999,0),0)} -> 강승모 | G62: ㅇ | H62: {=INDEX(Sheet1!$H$2:$H$9999,MATCH(D62,Sheet1!$D$2:$D$9999,0),0)} -> X
A63: {=INDEX(은행코드!$B$1:$B$24,MATCH(E63,은행코드!$A$1:$A$24,0),0)} -> 003 | B63: {=INDEX(Sheet1!$B$2:$B$9999,MATCH(D63,Sheet1!$D$2:$D$9999,0),0)} -> 41505575601011 | C63: 36000 | D63: 럽모어 | E63: {=INDEX(Sheet1!$E$2:$E$9999,MATCH(D63,Sheet1!$D$2:$D$9999,0),0)} -> 기업 | F63: {=INDEX(Sheet1!$F$2:$F$9999,MATCH(D63,Sheet1!$D$2:$D$9999,0),0)} -> 윤은지 | G63: ㅇ | H63: {=INDEX(Sheet1!$H$2:$H$9999,MATCH(D63,Sheet1!$D$2:$D$9999,0),0)} -> X
A64: {=INDEX(은행코드!$B$1:$B$24,MATCH(E64,은행코드!$A$1:$A$24,0),0)} -> 020 | B64: {=INDEX(Sheet1!$B$2:$B$9999,MATCH(D64,Sheet1!$D$2:$D$9999,0),0)} -> 1005304084206 | C64: 13000 | D64: 따봉 | E64: {=INDEX(Sheet1!$E$2:$E$9999,MATCH(D64,Sheet1!$D$2:$D$9999,0),0)} -> 우리 | F64: {=INDEX(Sheet1!$F$2:$F$9999,MATCH(D64,Sheet1!$D$2:$D$9999,0),0)} -> 주식회사 따봉 | G64: ㅇ | H64: {=INDEX(Sheet1!$H$2:$H$9999,MATCH(D64,Sheet1!$D$2:$D$9999,0),0)} -> X
A65: {=INDEX(은행코드!$B$1:$B$24,MATCH(E65,은행코드!$A$1:$A$24,0),0)} -> 088 | B65: {=INDEX(Sheet1!$B$2:$B$9999,MATCH(D65,Sheet1!$D$2:$D$9999,0),0)} -> 140014314677 | C65: 48000 | D65: 디티엠 | E65: {=INDEX(Sheet1!$E$2:$E$9999,MATCH(D65,Sheet1!$D$2:$D$9999,0),0)} -> 신한 | F65: {=INDEX(Sheet1!$F$2:$F$9999,MATCH(D65,Sheet1!$D$2:$D$9999,0),0)} -> ㈜위원트 | G65: ㅇ | H65: {=INDEX(Sheet1!$H$2:$H$9999,MATCH(D65,Sheet1!$D$2:$D$9999,0),0)} -> X
A66: {=INDEX(은행코드!$B$1:$B$24,MATCH(E66,은행코드!$A$1:$A$24,0),0)} -> 088 | B66: {=INDEX(Sheet1!$B$2:$B$9999,MATCH(D66,Sheet1!$D$2:$D$9999,0),0)} -> 140013719007 | C66: 10000 | D66: 디어 | E66: {=INDEX(Sheet1!$E$2:$E$9999,MATCH(D66,Sheet1!$D$2:$D$9999,0),0)} -> 신한 | F66: {=INDEX(Sheet1!$F$2:$F$9999,MATCH(D66,Sheet1!$D$2:$D$9999,0),0)} -> ㈜패션컴퍼니오성 | G66: ㅇ | H66: {=INDEX(Sheet1!$H$2:$H$9999,MATCH(D66,Sheet1!$D$2:$D$9999,0),0)} -> X
A67: {=INDEX(은행코드!$B$1:$B$24,MATCH(E67,은행코드!$A$1:$A$24,0),0)} -> 081 | B67: {=INDEX(Sheet1!$B$2:$B$9999,MATCH(D67,Sheet1!$D$2:$D$9999,0),0)} -> 28091001968104 | C67: 44000 | D67: 디벨롭 | E67: {=INDEX(Sheet1!$E$2:$E$9999,MATCH(D67,Sheet1!$D$2:$D$9999,0),0)} -> 하나 | F67: {=INDEX(Sheet1!$F$2:$F$9999,MATCH(D67,Sheet1!$D$2:$D$9999,0),0)} -> 주식회사 앰엔디 | G67: ㅇ | H67: {=INDEX(Sheet1!$H$2:$H$9999,MATCH(D67,Sheet1!$D$2:$D$9999,0),0)} -> X
A68: {=INDEX(은행코드!$B$1:$B$24,MATCH(E68,은행코드!$A$1:$A$24,0),0)} -> 004 | B68: {=INDEX(Sheet1!$B$2:$B$9999,MATCH(D68,Sheet1!$D$2:$D$9999,0),0)} -> 80753704011432 | C68: 18000 | D68: 디반 | E68: {=INDEX(Sheet1!$E$2:$E$9999,MATCH(D68,Sheet1!$D$2:$D$9999,0),0)} -> 국민 | F68: {=INDEX(Sheet1!$F$2:$F$9999,MATCH(D68,Sheet1!$D$2:$D$9999,0),0)} -> 이반석(디반(DBAN)) | G68: ㅇ | H68: {=INDEX(Sheet1!$H$2:$H$9999,MATCH(D68,Sheet1!$D$2:$D$9999,0),0)} -> X
A69: {=INDEX(은행코드!$B$1:$B$24,MATCH(E69,은행코드!$A$1:$A$24,0),0)} -> 003 | B69: {=INDEX(Sheet1!$B$2:$B$9999,MATCH(D69,Sheet1!$D$2:$D$9999,0),0)} -> 01818868201016 | C69: 314600 | D69: 더블유모즈 | E69: {=INDEX(Sheet1!$E$2:$E$9999,MATCH(D69,Sheet1!$D$2:$D$9999,0),0)} -> 기업 | F69: {=INDEX(Sheet1!$F$2:$F$9999,MATCH(D69,Sheet1!$D$2:$D$9999,0),0)} -> ㈜모즈패션 | G69: ㅇ | H69: {=INDEX(Sheet1!$H$2:$H$9999,MATCH(D69,Sheet1!$D$2:$D$9999,0),0)} -> O
A70: {=INDEX(은행코드!$B$1:$B$24,MATCH(E70,은행코드!$A$1:$A$24,0),0)} -> 081 | B70: {=INDEX(Sheet1!$B$2:$B$9999,MATCH(D70,Sheet1!$D$2:$D$9999,0),0)} -> 15391063644307 | C70: 9000 | D70: 논제 | E70: {=INDEX(Sheet1!$E$2:$E$9999,MATCH(D70,Sheet1!$D$2:$D$9999,0),0)} -> 하나 | F70: {=INDEX(Sheet1!$F$2:$F$9999,MATCH(D70,Sheet1!$D$2:$D$9999,0),0)} -> 논제 | G70: ㅇ | H70: {=INDEX(Sheet1!$H$2:$H$9999,MATCH(D70,Sheet1!$D$2:$D$9999,0),0)} -> X
A71: {=INDEX(은행코드!$B$1:$B$24,MATCH(E71,은행코드!$A$1:$A$24,0),0)} -> 088 | B71: {=INDEX(Sheet1!$B$2:$B$9999,MATCH(D71,Sheet1!$D$2:$D$9999,0),0)} -> 100031530371 | C71: 194000 | D71: 그랑블루 | E71: {=INDEX(Sheet1!$E$2:$E$9999,MATCH(D71,Sheet1!$D$2:$D$9999,0),0)} -> 신한 | F71: {=INDEX(Sheet1!$F$2:$F$9999,MATCH(D71,Sheet1!$D$2:$D$9999,0),0)} -> ㈜그랑블루진 | G71: ㅇ | H71: {=INDEX(Sheet1!$H$2:$H$9999,MATCH(D71,Sheet1!$D$2:$D$9999,0),0)} -> X
... A73: {=INDEX(은행코드!$B$1:$B$24,MATCH(E73,은행코드!$A$1:$A$24,0),0)} -> 088 | B73: {=INDEX(Sheet1!$B$2:$B$9999,MATCH(D73,Sheet1!$D$2:$D$9999,0),0)} -> 34802627001 | C73: 108000 | D73: 구이공 | E73: {=INDEX(Sheet1!$E$2:$E$9999,MATCH(D73,Sheet1!$D$2:$D$9999,0),0)} -> 신한 | F73: {=INDEX(Sheet1!$F$2:$F$9999,MATCH(D73,Sheet1!$D$2:$D$9999,0),0)} -> 박영규(구이공) | G73: ㅇ | H73: {=INDEX(Sheet1!$H$2:$H$9999,MATCH(D73,Sheet1!$D$2:$D$9999,0),0)} -> x

Sheet 2월 2일
A1: D | B1: D | C1: D | D1: D | E1: D | F1: D | G1: D | H1: D
A2: {=INDEX(은행코드!$B$1:$B$24,MATCH(E2,은행코드!$A$1:$A$24,0),0)} -> 020 | B2: {=INDEX(Sheet1!$B$2:$B$9999,MATCH(D2,Sheet1!$D$2:$D$9999,0),0)} -> 1005504775443 | C2: 153000 | D2: 히피스 | E2: {=INDEX(Sheet1!$E$2:$E$9999,MATCH(D2,Sheet1!$D$2:$D$9999,0),0)} -> 우리 | F2: {=INDEX(Sheet1!$F$2:$F$9999,MATCH(D2,Sheet1!$D$2:$D$9999,0),0)} -> 이도영(히피스) | G2: ㅇ | H2: {=INDEX(Sheet1!$H$2:$H$9999,MATCH(D2,Sheet1!$D$2:$D$9999,0),0)} -> X
A3: {=INDEX(은행코드!$B$1:$B$24,MATCH(E3,은행코드!$A$1:$A$24,0),0)} -> 003 | B3: {=INDEX(Sheet1!$B$2:$B$9999,MATCH(D3,Sheet1!$D$2:$D$9999,0),0)} -> 20108343304014 | C3: 12000 | D3: 화이트옐로우 | E3: {=INDEX(Sheet1!$E$2:$E$9999,MATCH(D3,Sheet1!$D$2:$D$9999,0),0)} -> 기업 | F3: {=INDEX(Sheet1!$F$2:$F$9999,MATCH(D3,Sheet1!$D$2:$D$9999,0),0)} -> 옐로우이엔엠 주식회사 | G3: ㅇ | H3: {=INDEX(Sheet1!$H$2:$H$9999,MATCH(D3,Sheet1!$D$2:$D$9999,0),0)} -> X
A4: {=INDEX(은행코드!$B$1:$B$24,MATCH(E4,은행코드!$A$1:$A$24,0),0)} -> 090 | B4: {=INDEX(Sheet1!$B$2:$B$9999,MATCH(D4,Sheet1!$D$2:$D$9999,0),0)} -> 3333289511795 | C4: 27000 | D4: 하이프 | E4: {=INDEX(Sheet1!$E$2:$E$9999,MATCH(D4,Sheet1!$D$2:$D$9999,0),0)} -> 카카오 | F4: {=INDEX(Sheet1!$F$2:$F$9999,MATCH(D4,Sheet1!$D$2:$D$9999,0),0)} -> 하이프(HYPE) | G4: ㅇ | H4: {=INDEX(Sheet1!$H$2:$H$9999,MATCH(D4,Sheet1!$D$2:$D$9999,0),0)} -> X
A5: {=INDEX(은행코드!$B$1:$B$24,MATCH(E5,은행코드!$A$1:$A$24,0),0)} -> 081 | B5: {=INDEX(Sheet1!$B$2:$B$9999,MATCH(D5,Sheet1!$D$2:$D$9999,0),0)} -> 17191028203607 | C5: 90000 | D5: 하이바 | E5: {=INDEX(Sheet1!$E$2:$E$9999,MATCH(D5,Sheet1!$D$2:$D$9999,0),0)} -> 하나 | F5: {=INDEX(Sheet1!$F$2:$F$9999,MATCH(D5,Sheet1!$D$2:$D$9999,0),0)} -> 김태형 | G5: ㅇ | H5: {=INDEX(Sheet1!$H$2:$H$9999,MATCH(D5,Sheet1!$D$2:$D$9999,0),0)} -> X
A6: {=INDEX(은행코드!$B$1:$B$24,MATCH(E6,은행코드!$A$1:$A$24,0),0)} -> 004 | B6: {=INDEX(Sheet1!$B$2:$B$9999,MATCH(D6,Sheet1!$D$2:$D$9999,0),0)} -> 79660104124093 | C6: 19000 | D6: 하루하 | E6: {=INDEX(Sheet1!$E$2:$E$9999,MATCH(D6,Sheet1!$D$2:$D$9999,0),0)} -> 국민 | F6: {=INDEX(Sheet1!$F$2:$F$9999,MATCH(D6,Sheet1!$D$2:$D$9999,0),0)} -> 하루하 | G6: ㅇ | H6: {=INDEX(Sheet1!$H$2:$H$9999,MATCH(D6,Sheet1!$D$2:$D$9999,0),0)} -> X
A7: {=INDEX(은행코드!$B$1:$B$24,MATCH(E7,은행코드!$A$1:$A$24,0),0)} -> 004 | B7: {=INDEX(Sheet1!$B$2:$B$9999,MATCH(D7,Sheet1!$D$2:$D$9999,0),0)} -> 80750104288480 | C7: 30500 | D7: 필앤마조 | E7: {=INDEX(Sheet1!$E$2:$E$9999,MATCH(D7,Sheet1!$D$2:$D$9999,0),0)} -> 국민 | F7: {=INDEX(Sheet1!$F$2:$F$9999,MATCH(D7,Sheet1!$D$2:$D$9999,0),0)} -> (주)필앤마조 | G7: ㅇ | H7: {=INDEX(Sheet1!$H$2:$H$9999,MATCH(D7,Sheet1!$D$2:$D$9999,0),0)} -> X
A8: {=INDEX(은행코드!$B$1:$B$24,MATCH(E8,은행코드!$A$1:$A$24,0),0)} -> 003 | B8: {=INDEX(Sheet1!$B$2:$B$9999,MATCH(D8,Sheet1!$D$2:$D$9999,0),0)} -> 01041961598 | C8: 26000 | D8: 플레이 | E8: {=INDEX(Sheet1!$E$2:$E$9999,MATCH(D8,Sheet1!$D$2:$D$9999,0),0)} -> 기업 | F8: {=INDEX(Sheet1!$F$2:$F$9999,MATCH(D8,Sheet1!$D$2:$D$9999,0),0)} -> 김미라(플레이) | G8: ㅇ | H8: {=INDEX(Sheet1!$H$2:$H$9999,MATCH(D8,Sheet1!$D$2:$D$9999,0),0)} -> X
A9: {=INDEX(은행코드!$B$1:$B$24,MATCH(E9,은행코드!$A$1:$A$24,0),0)} -> 088 | B9: {=INDEX(Sheet1!$B$2:$B$9999,MATCH(D9,Sheet1!$D$2:$D$9999,0),0)} -> 140013540787 | C9: 13000 | D9: 풀하우스 | E9: {=INDEX(Sheet1!$E$2:$E$9999,MATCH(D9,Sheet1!$D$2:$D$9999,0),0)} -> 신한 | F9: {=INDEX(Sheet1!$F$2:$F$9999,MATCH(D9,Sheet1!$D$2:$D$9999,0),0)} -> 주식회사 풀하우스컴퍼니 김기완 | G9: ㅇ | H9: {=INDEX(Sheet1!$H$2:$H$9999,MATCH(D9,Sheet1!$D$2:$D$9999,0),0)} -> X
A10: {=INDEX(은행코드!$B$1:$B$24,MATCH(E10,은행코드!$A$1:$A$24,0),0)} -> 090 | B10: {=INDEX(Sheet1!$B$2:$B$9999,MATCH(D10,Sheet1!$D$2:$D$9999,0),0)} -> 3333123250772 | C10: 90000 | D10: 포레나 | E10: {=INDEX(Sheet1!$E$2:$E$9999,MATCH(D10,Sheet1!$D$2:$D$9999,0),0)} -> 카카오 | F10: {=INDEX(Sheet1!$F$2:$F$9999,MATCH(D10,Sheet1!$D$2:$D$9999,0),0)} -> 박진성 | G10: ㅇ | H10: {=INDEX(Sheet1!$H$2:$H$9999,MATCH(D10,Sheet1!$D$2:$D$9999,0),0)} -> X
A11: {=INDEX(은행코드!$B$1:$B$24,MATCH(E11,은행코드!$A$1:$A$24,0),0)} -> 088 | B11: {=INDEX(Sheet1!$B$2:$B$9999,MATCH(D11,Sheet1!$D$2:$D$9999,0),0)} -> 110316175919 | C11: 72000 | D11: 페어립트 | E11: {=INDEX(Sheet1!$E$2:$E$9999,MATCH(D11,Sheet1!$D$2:$D$9999,0),0)} -> 신한 | F11: {=INDEX(Sheet1!$F$2:$F$9999,MATCH(D11,Sheet1!$D$2:$D$9999,0),0)} -> 황두환(페어립트) | G11: ㅇ | H11: {=INDEX(Sheet1!$H$2:$H$9999,MATCH(D11,Sheet1!$D$2:$D$9999,0),0)} -> X
A12: {=INDEX(은행코드!$B$1:$B$24,MATCH(E12,은행코드!$A$1:$A$24,0),0)} -> 003 | B12: {=INDEX(Sheet1!$B$2:$B$9999,MATCH(D12,Sheet1!$D$2:$D$9999,0),0)} -> 01819320404015 | C12: 12100 | D12: 퍼플그레이 | E12: {=INDEX(Sheet1!$E$2:$E$9999,MATCH(D12,Sheet1!$D$2:$D$9999,0),0)} -> 기업 | F12: {=INDEX(Sheet1!$F$2:$F$9999,MATCH(D12,Sheet1!$D$2:$D$9999,0),0)} -> ㈜퍼플그레이어패럴 | G12: ㅇ | H12: {=INDEX(Sheet1!$H$2:$H$9999,MATCH(D12,Sheet1!$D$2:$D$9999,0),0)} -> O
A13: {=INDEX(은행코드!$B$1:$B$24,MATCH(E13,은행코드!$A$1:$A$24,0),0)} -> 088 | B13: {=INDEX(Sheet1!$B$2:$B$9999,MATCH(D13,Sheet1!$D$2:$D$9999,0),0)} -> 110489581929 | C13: 14000 | D13: 팔로우비 | E13: {=INDEX(Sheet1!$E$2:$E$9999,MATCH(D13,Sheet1!$D$2:$D$9999,0),0)} -> 신한 | F13: {=INDEX(Sheet1!$F$2:$F$9999,MATCH(D13,Sheet1!$D$2:$D$9999,0),0)} -> 변입섭 팔로우비 | G13: ㅇ | H13: {=INDEX(Sheet1!$H$2:$H$9999,MATCH(D13,Sheet1!$D$2:$D$9999,0),0)} -> X
... A30: {=INDEX(은행코드!$B$1:$B$24,MATCH(E30,은행코드!$A$1:$A$24,0),0)} -> 004 | B30: {=INDEX(Sheet1!$B$2:$B$9999,MATCH(D30,Sheet1!$D$2:$D$9999,0),0)} -> 06880104407136 | C30: 14000 | D30: 웨이비 | E30: {=INDEX(Sheet1!$E$2:$E$9999,MATCH(D30,Sheet1!$D$2:$D$9999,0),0)} -> 국민 | F30: {=INDEX(Sheet1!$F$2:$F$9999,MATCH(D30,Sheet1!$D$2:$D$9999,0),0)} -> 웨이비 임솔 | G30: ㅇ | H30: {=INDEX(Sheet1!$H$2:$H$9999,MATCH(D30,Sheet1!$D$2:$D$9999,0),0)} -> X
A31: {=INDEX(은행코드!$B$1:$B$24,MATCH(E31,은행코드!$A$1:$A$24,0),0)} -> 003 | B31: 03014341201010 | C31: 12000 | D31: 원 | E31: 기업 | F31: 윤채원 | G31: ㅇ | H31: X
A32: {=INDEX(은행코드!$B$1:$B$24,MATCH(E32,은행코드!$A$1:$A$24,0),0)} -> 020 | B32: {=INDEX(Sheet1!$B$2:$B$9999,MATCH(D32,Sheet1!$D$2:$D$9999,0),0)} -> 1005104702925 | C32: 41000 | D32: 우트 | E32: {=INDEX(Sheet1!$E$2:$E$9999,MATCH(D32,Sheet1!$D$2:$D$9999,0),0)} -> 우리 | F32: {=INDEX(Sheet1!$F$2:$F$9999,MATCH(D32,Sheet1!$D$2:$D$9999,0),0)} -> ㈜오오티제이 오리진 | G32: ㅇ | H32: {=INDEX(Sheet1!$H$2:$H$9999,MATCH(D32,Sheet1!$D$2:$D$9999,0),0)} -> O
A33: {=INDEX(은행코드!$B$1:$B$24,MATCH(E33,은행코드!$A$1:$A$24,0),0)} -> 088 | B33: {=INDEX(Sheet1!$B$2:$B$9999,MATCH(D33,Sheet1!$D$2:$D$9999,0),0)} -> 110474414886 | C33: 6000 | D33: 와이파이 | E33: {=INDEX(Sheet1!$E$2:$E$9999,MATCH(D33,Sheet1!$D$2:$D$9999,0),0)} -> 신한 | F33: {=INDEX(Sheet1!$F$2:$F$9999,MATCH(D33,Sheet1!$D$2:$D$9999,0),0)} -> 김예근(WIFI) | G33: ㅇ | H33: {=INDEX(Sheet1!$H$2:$H$9999,MATCH(D33,Sheet1!$D$2:$D$9999,0),0)} -> X
A34: {=INDEX(은행코드!$B$1:$B$24,MATCH(E34,은행코드!$A$1:$A$24,0),0)} -> 088 | B34: {=INDEX(Sheet1!$B$2:$B$9999,MATCH(D34,Sheet1!$D$2:$D$9999,0),0)} -> 140012598030 | C34: 15950 | D34: 오즈브릿지 | E34: {=INDEX(Sheet1!$E$2:$E$9999,MATCH(D34,Sheet1!$D$2:$D$9999,0),0)} -> 신한 | F34: {=INDEX(Sheet1!$F$2:$F$9999,MATCH(D34,Sheet1!$D$2:$D$9999,0),0)} -> ㈜오즈브릿지 | G34: ㅇ | H34: {=INDEX(Sheet1!$H$2:$H$9999,MATCH(D34,Sheet1!$D$2:$D$9999,0),0)} -> ㅇ
A35: {=INDEX(은행코드!$B$1:$B$24,MATCH(E35,은행코드!$A$1:$A$24,0),0)} -> 088 | B35: {=INDEX(Sheet1!$B$2:$B$9999,MATCH(D35,Sheet1!$D$2:$D$9999,0),0)} -> 140015691630 | C35: 74500 | D35: 오드 | E35: {=INDEX(Sheet1!$E$2:$E$9999,MATCH(D35,Sheet1!$D$2:$D$9999,0),0)} -> 신한 | F35: {=INDEX(Sheet1!$F$2:$F$9999,MATCH(D35,Sheet1!$D$2:$D$9999,0),0)} -> 주식회사 오드점 | G35: ㅇ | H35: {=INDEX(Sheet1!$H$2:$H$9999,MATCH(D35,Sheet1!$D$2:$D$9999,0),0)} -> X
A36: {=INDEX(은행코드!$B$1:$B$24,MATCH(E36,은행코드!$A$1:$A$24,0),0)} -> 088 | B36: {=INDEX(Sheet1!$B$2:$B$9999,MATCH(D36,Sheet1!$D$2:$D$9999,0),0)} -> 110555467484 | C36: 8000 | D36: 오도시 | E36: {=INDEX(Sheet1!$E$2:$E$9999,MATCH(D36,Sheet1!$D$2:$D$9999,0),0)} -> 신한 | F36: {=INDEX(Sheet1!$F$2:$F$9999,MATCH(D36,Sheet1!$D$2:$D$9999,0),0)} -> 임창현/오도시 | G36: ㅇ | H36: {=INDEX(Sheet1!$H$2:$H$9999,MATCH(D36,Sheet1!$D$2:$D$9999,0),0)} -> X
A37: {=INDEX(은행코드!$B$1:$B$24,MATCH(E37,은행코드!$A$1:$A$24,0),0)} -> 020 | B37: {=INDEX(Sheet1!$B$2:$B$9999,MATCH(D37,Sheet1!$D$2:$D$9999,0),0)} -> 1005504495386 | C37: 161000 | D37: 여기 | E37: {=INDEX(Sheet1!$E$2:$E$9999,MATCH(D37,Sheet1!$D$2:$D$9999,0),0)} -> 우리 | F37: {=INDEX(Sheet1!$F$2:$F$9999,MATCH(D37,Sheet1!$D$2:$D$9999,0),0)} -> 에브리웨어 | G37: ㅇ | H37: {=INDEX(Sheet1!$H$2:$H$9999,MATCH(D37,Sheet1!$D$2:$D$9999,0),0)} -> X
A38: {=INDEX(은행코드!$B$1:$B$24,MATCH(E38,은행코드!$A$1:$A$24,0),0)} -> 088 | B38: {=INDEX(Sheet1!$B$2:$B$9999,MATCH(D38,Sheet1!$D$2:$D$9999,0),0)} -> 140013987091 | C38: 46000 | D38: 엣지 | E38: {=INDEX(Sheet1!$E$2:$E$9999,MATCH(D38,Sheet1!$D$2:$D$9999,0),0)} -> 신한 | F38: {=INDEX(Sheet1!$F$2:$F$9999,MATCH(D38,Sheet1!$D$2:$D$9999,0),0)} -> ㈜이디지이(EDGE) | G38: ㅇ | H38: {=INDEX(Sheet1!$H$2:$H$9999,MATCH(D38,Sheet1!$D$2:$D$9999,0),0)} -> X
A39: {=INDEX(은행코드!$B$1:$B$24,MATCH(E39,은행코드!$A$1:$A$24,0),0)} -> 088 | B39: {=INDEX(Sheet1!$B$2:$B$9999,MATCH(D39,Sheet1!$D$2:$D$9999,0),0)} -> 110517059780 | C39: 31900 | D39: 엔초 | E39: {=INDEX(Sheet1!$E$2:$E$9999,MATCH(D39,Sheet1!$D$2:$D$9999,0),0)} -> 신한 | F39: {=INDEX(Sheet1!$F$2:$F$9999,MATCH(D39,Sheet1!$D$2:$D$9999,0),0)} -> 최훈정(엔초) | G39: ㅇ | H39: {=INDEX(Sheet1!$H$2:$H$9999,MATCH(D39,Sheet1!$D$2:$D$9999,0),0)} -> O
A40: {=INDEX(은행코드!$B$1:$B$24,MATCH(E40,은행코드!$A$1:$A$24,0),0)} -> 003 | B40: {=INDEX(Sheet1!$B$2:$B$9999,MATCH(D40,Sheet1!$D$2:$D$9999,0),0)} -> 02908577101019 | C40: 77000 | D40: 에이에이더블유 | E40: {=INDEX(Sheet1!$E$2:$E$9999,MATCH(D40,Sheet1!$D$2:$D$9999,0),0)} -> 기업 | F40: {=INDEX(Sheet1!$F$2:$F$9999,MATCH(D40,Sheet1!$D$2:$D$9999,0),0)} -> 에이에이더블유(권지영) | G40: ㅇ | H40: {=INDEX(Sheet1!$H$2:$H$9999,MATCH(D40,Sheet1!$D$2:$D$9999,0),0)} -> O
A41: {=INDEX(은행코드!$B$1:$B$24,MATCH(E41,은행코드!$A$1:$A$24,0),0)} -> 003 | B41: {=INDEX(Sheet1!$B$2:$B$9999,MATCH(D41,Sheet1!$D$2:$D$9999,0),0)} -> 01093570559 | C41: 9000 | D41: 야나 | E41: {=INDEX(Sheet1!$E$2:$E$9999,MATCH(D41,Sheet1!$D$2:$D$9999,0),0)} -> 기업 | F41: {=INDEX(Sheet1!$F$2:$F$9999,MATCH(D41,Sheet1!$D$2:$D$9999,0),0)} -> 김정훈(야나) | G41: ㅇ | H41: {=INDEX(Sheet1!$H$2:$H$9999,MATCH(D41,Sheet1!$D$2:$D$9999,0),0)} -> X
A42: {=INDEX(은행코드!$B$1:$B$24,MATCH(E42,은행코드!$A$1:$A$24,0),0)} -> 088 | B42: {=INDEX(Sheet1!$B$2:$B$9999,MATCH(D42,Sheet1!$D$2:$D$9999,0),0)} -> 110547690282 | C42: 12000 | D42: 앨리 | E42: {=INDEX(Sheet1!$E$2:$E$9999,MATCH(D42,Sheet1!$D$2:$D$9999,0),0)} -> 신한 | F42: {=INDEX(Sheet1!$F$2:$F$9999,MATCH(D42,Sheet1!$D$2:$D$9999,0),0)} -> 신나겸이(앨리) | G42: ㅇ | H42: {=INDEX(Sheet1!$H$2:$H$9999,MATCH(D42,Sheet1!$D$2:$D$9999,0),0)} -> X
A43: {=INDEX(은행코드!$B$1:$B$24,MATCH(E43,은행코드!$A$1:$A$24,0),0)} -> 088 | B43: {=INDEX(Sheet1!$B$2:$B$9999,MATCH(D43,Sheet1!$D$2:$D$9999,0),0)} -> 110539887153 | C43: 240000 | D43: 안나 | E43: {=INDEX(Sheet1!$E$2:$E$9999,MATCH(D43,Sheet1!$D$2:$D$9999,0),0)} -> 신한 | F43: {=INDEX(Sheet1!$F$2:$F$9999,MATCH(D43,Sheet1!$D$2:$D$9999,0),0)} -> 김수진 | G43: ㅇ | H43: {=INDEX(Sheet1!$H$2:$H$9999,MATCH(D43,Sheet1!$D$2:$D$9999,0),0)} -> X
... A91: {=INDEX(은행코드!$B$1:$B$24,MATCH(E91,은행코드!$A$1:$A$24,0),0)} -> 004 | B91: {=INDEX(Sheet1!$B$2:$B$9999,MATCH(D91,Sheet1!$D$2:$D$9999,0),0)} -> 01830104233866 | C91: 56100 | D91: 계란속노른자 | E91: {=INDEX(Sheet1!$E$2:$E$9999,MATCH(D91,Sheet1!$D$2:$D$9999,0),0)} -> 국민 | F91: {=INDEX(Sheet1!$F$2:$F$9999,MATCH(D91,Sheet1!$D$2:$D$9999,0),0)} -> 김재영 | G91: ㅇ | H91: {=INDEX(Sheet1!$H$2:$H$9999,MATCH(D91,Sheet1!$D$2:$D$9999,0),0)} -> O

Sheet 2월 3일
A1: ㅇ | B1: ㅇ | C1: ㅇ | D1: ㅇ | E1: ㅇ | F1: ㅇ | G1: ㅇ | H1: ㅇ
A2: {=INDEX(은행코드!$B$1:$B$24,MATCH(E2,은행코드!$A$1:$A$24,0),0)} -> 020 | B2: {=INDEX(Sheet1!$B$2:$B$9999,MATCH(D2,Sheet1!$D$2:$D$9999,0),0)} -> 1005603106537 | C2: 135000 | D2: 힙블리 | E2: {=INDEX(Sheet1!$E$2:$E$9999,MATCH(D2,Sheet1!$D$2:$D$9999,0),0)} -> 우리 | F2: {=INDEX(Sheet1!$F$2:$F$9999,MATCH(D2,Sheet1!$D$2:$D$9999,0),0)} -> 오승미 | G2: ㅇ | H2: {=INDEX(Sheet1!$H$2:$H$9999,MATCH(D2,Sheet1!$D$2:$D$9999,0),0)} -> x
A3: {=INDEX(은행코드!$B$1:$B$24,MATCH(E3,은행코드!$A$1:$A$24,0),0)} -> 090 | B3: {=INDEX(Sheet1!$B$2:$B$9999,MATCH(D3,Sheet1!$D$2:$D$9999,0),0)} -> 3333289511795 | C3: 54000 | D3: 하이프 | E3: {=INDEX(Sheet1!$E$2:$E$9999,MATCH(D3,Sheet1!$D$2:$D$9999,0),0)} -> 카카오 | F3: {=INDEX(Sheet1!$F$2:$F$9999,MATCH(D3,Sheet1!$D$2:$D$9999,0),0)} -> 하이프(HYPE) | G3: ㅇ | H3: {=INDEX(Sheet1!$H$2:$H$9999,MATCH(D3,Sheet1!$D$2:$D$9999,0),0)} -> X
A4: {=INDEX(은행코드!$B$1:$B$24,MATCH(E4,은행코드!$A$1:$A$24,0),0)} -> 088 | B4: {=INDEX(Sheet1!$B$2:$B$9999,MATCH(D4,Sheet1!$D$2:$D$9999,0),0)} -> 110554774968 | C4: 108000 | D4: 하이앤땡큐 | E4: {=INDEX(Sheet1!$E$2:$E$9999,MATCH(D4,Sheet1!$D$2:$D$9999,0),0)} -> 신한 | F4: {=INDEX(Sheet1!$F$2:$F$9999,MATCH(D4,Sheet1!$D$2:$D$9999,0),0)} -> 김승현 | G4: ㅇ | H4: {=INDEX(Sheet1!$H$2:$H$9999,MATCH(D4,Sheet1!$D$2:$D$9999,0),0)} -> X
A5: {=INDEX(은행코드!$B$1:$B$24,MATCH(E5,은행코드!$A$1:$A$24,0),0)} -> 081 | B5: {=INDEX(Sheet1!$B$2:$B$9999,MATCH(D5,Sheet1!$D$2:$D$9999,0),0)} -> 17191028203607 | C5: 9000 | D5: 하이바 | E5: {=INDEX(Sheet1!$E$2:$E$9999,MATCH(D5,Sheet1!$D$2:$D$9999,0),0)} -> 하나 | F5: {=INDEX(Sheet1!$F$2:$F$9999,MATCH(D5,Sheet1!$D$2:$D$9999,0),0)} -> 김태형 | G5: ㅇ | H5: {=INDEX(Sheet1!$H$2:$H$9999,MATCH(D5,Sheet1!$D$2:$D$9999,0),0)} -> X
A6: {=INDEX(은행코드!$B$1:$B$24,MATCH(E6,은행코드!$A$1:$A$24,0),0)} -> 004 | B6: {=INDEX(Sheet1!$B$2:$B$9999,MATCH(D6,Sheet1!$D$2:$D$9999,0),0)} -> 80750104288480 | C6: 18000 | D6: 필앤마조 | E6: {=INDEX(Sheet1!$E$2:$E$9999,MATCH(D6,Sheet1!$D$2:$D$9999,0),0)} -> 국민 | F6: {=INDEX(Sheet1!$F$2:$F$9999,MATCH(D6,Sheet1!$D$2:$D$9999,0),0)} -> (주)필앤마조 | G6: ㅇ | H6: {=INDEX(Sheet1!$H$2:$H$9999,MATCH(D6,Sheet1!$D$2:$D$9999,0),0)} -> X
